Workbook
Name Banner: Names!$B$60
Name Heat_15: '10 Cars'!$H$2
Name Heat_15: '11 Cars'!$H$2
Name Heat_15: '12 Cars'!$H$2
Name Heat_15: '13 Cars'!$H$2
Name Heat_15: '14 Cars'!$H$2
Name Heat_15: '15 Cars'!$H$2
Name Heat_15: '16 Cars'!$H$2
Name Heat_15: '17 Cars'!$H$2
Name Heat_15: '18 Cars'!$H$2
Name Heat_15: '19 Cars'!$H$2
Name Heat_15: '20 Cars'!$H$2
Name Heat_15: '21 Cars'!$H$2
Name Heat_15: '22 Cars'!$H$2
Name Heat_15: '23 Cars'!$H$2
Name Heat_15: '24 Cars'!$H$2
Name Heat_15: '25 Cars'!$H$2
Name Heat_15: '4 Cars'!$H$2
Name Heat_15: '5 Cars'!$H$2
Name Heat_15: '6 Cars'!$H$2
Name Heat_15: '7 Cars'!$H$2
Name Heat_15: '8 Cars'!$H$2
Name Heat_15: '9 Cars'!$H$2
Name Heat_15: #REF!
Name Racer1: Names!$A$2&" - "&Names!$B$2
Name Racer10: Names!$A$11&" - "&Names!$B$11
Name Racer11: Names!$A$17&" - "&Names!$B$20
Name Racer12: Names!$A$18&" - "&Names!$B$18
Name Racer13: Names!$A$19&" - "&Names!#REF!
Name Racer14: Names!$A$20&" - "&Names!#REF!
Name Racer15: Names!$A$21&" - "&Names!$B$21
Name Racer2: Names!$A$3&" - "&Names!$B$3
Name Racer3: Names!$A$4&" - "&Names!$B$4
Name Racer4: Names!$A$5&" - "&Names!$B$5
Name Racer5: Names!$A$6&" - "&Names!$B$6
Name Racer6: Names!$A$7&" - "&Names!$B$7
Name Racer7: Names!$A$8&" - "&Names!$B$8
Name Racer8: Names!$A$9&" - "&Names!$B$9
Name Racer9: Names!$A$10&" - "&Names!$B$10

Sheet Readme
A1: Pinewood Derby Scoring
A3: Developed by Bob Baggerman, bob@scoutdb.org (17 Jan 2005)
A4: The race order is based on the Partial Perfect-N (PPN) Charts
A5: A PPN chart is one which satisfies these conditions:
A6: 1. Each car races the same number of times in each lane (which implies that the number 'of races is a multiple of the number of cars)
A7: 2. Equality of opposition is optimized, i.e., no head to head matchup count exceeds another by more than 1.
A8: See "http://members.aol.com/StanDCmr/ppngen.html" for more details'
A10: How to use the scoring spreadsheet
A12: This scoring spreadsheet can handle from 3 to 15 racers. Cub scout names and car numbers are entered in the "Names" sheet before the race. Start entering names and car numbers on line 2 and don't skip any lines. Put the den title or other title in C1.
A13: After all racers have been entered, select the appropriate scoring sheet for the number of cars.
A14: During the race, select the current heat by entering the heat number in cell H2. The current heat names and car numbers show up at the top.
A15: When a heat has been run, enter the lane number for the 1st, 2nd, and 3rd finishes
... A36: In these column on the row for each heat are the lane assignments. A 1 means the first car from the Names sheet, 2 is the second car, etc. The cell formulas will work with any car lane assignments without changes.

Sheet Names
A1: Car Number | B1: Name | C1: Driver | E1: Trailblazers
A2: 1 | B2: Luke
A3: 2 | B3: Ro
A4: 3 | B4: Caleb
A5: 4 | B5: Zau
A6: 5 | B6: Brady
A7: 6 | B7: Theo
A8: 7 | B8: Jonathan
A9: 8 | B9: Brenton
A10: 9 | B10: Jospe
A11: 13 | B11: Emery
A12: 14 | B12: Isaac
A13: 23 | B13: Alain
... A17: 99 | B17: Cam
B60: Westminster Trailblazers Pinewood Derby

Sheet 25 Cars
F1: =+Banner -> Westminster Trailblazers Pinewood Derby
F2: Heat | H2: 1 | I2: =+Names!$C$1 -> Driver | M2: Finish | R2: Legend
F3: Lane 1 | H3: =INDIRECT(ADDRESS(INDIRECT(ADDRESS($H$2+9,2))+1,1,,,"Names")) -> 1 | I3: =INDIRECT(ADDRESS(INDIRECT(ADDRESS($H$2+9,2))+1,2,,,"Names")) -> Luke | M3: =IF(INDIRECT(ADDRESS(9+$H$2,11))=1,"1st",IF(INDIRECT(ADDRESS(9+$H$2,12))=1,"2nd",IF(INDIRECT(ADDRESS(9+$H$2,13))=1,"3rd"," "))) | N3: =IF($K3=4,3,IF($L3=4,2,IF($M3=4,1," "))) | S3: = 1st (3pts)
F4: Lane 2 | H4: =INDIRECT(ADDRESS(INDIRECT(ADDRESS($H$2+9,3))+1,1,,,"Names")) -> 3 | I4: =INDIRECT(ADDRESS(INDIRECT(ADDRESS($H$2+9,3))+1,2,,,"Names")) -> Caleb | M4: =IF(INDIRECT(ADDRESS(9+$H$2,11))=2,"1st",IF(INDIRECT(ADDRESS(9+$H$2,12))=2,"2nd",IF(INDIRECT(ADDRESS(9+$H$2,13))=2,"3rd"," "))) | N4: =IF($K4=4,3,IF($L4=4,2,IF($M4=4,1," "))) | S4: = 2nd (2pts)
F5: Lane 3 | H5: =INDIRECT(ADDRESS(INDIRECT(ADDRESS($H$2+9,4))+1,1,,,"Names")) -> 6 | I5: =INDIRECT(ADDRESS(INDIRECT(ADDRESS($H$2+9,4))+1,2,,,"Names")) -> Theo | M5: =IF(INDIRECT(ADDRESS(9+$H$2,11))=3,"1st",IF(INDIRECT(ADDRESS(9+$H$2,12))=3,"2nd",IF(INDIRECT(ADDRESS(9+$H$2,13))=3,"3rd"," "))) | N5: =IF($K5=4,3,IF($L5=4,2,IF($M5=4,1," "))) | S5: = 3rd (1pt)
G8: Car | K8: Lane Finish | N8: Points
F9: Heat | G9: Lane 1 | H9: Lane 2 | I9: Lane 3 | J9: Lane 4 | K9: 1st | L9: 2nd | M9: 3rd | N9: =+Names!$A$2 -> 1 | O9: =+Names!$A$3 -> 2 | P9: =+Names!$A$4 -> 3 | Q9: =+Names!$A$5 -> 4 | R9: =+Names!$A$6 -> 5 | S9: =+Names!$A$7 -> 6 | T9: =+Names!$A$8 -> 7 | U9: =+Names!$A$9 -> 8 | V9: =+Names!$A$10 -> 9 | W9: =+Names!$A$11 -> 13 | X9: =+Names!$A$12 -> 14 | Y9: =+Names!$A$13 -> 23 | Z9: =+Names!$A$14 -> 30 | AA9: =+Names!$A$15 -> 37 | AB9: =+Names!$A$16 -> 49 | AC9: =+Names!$A$17 -> 99 | AD9: =+Names!$A$18 -> 0 | AE9: =+Names!$A$19 -> 0 | AF9: =+Names!$A$20 -> 0 | AG9: =+Names!$A$21 -> 0 | AH9: =+Names!$A$22 -> 0 | AI9: =+Names!$A$23 -> 0 | AJ9: =+Names!$A$24 -> 0 | AK9: =+Names!$A$25 -> 0 | AL9: =+Names!$A$26 -> 0
B10: 1 | C10: 3 | D10: 6 | F10: 1 | G10: =INDIRECT(ADDRESS(B10+1,1,,,"Names")) -> 1 | H10: =INDIRECT(ADDRESS(C10+1,1,,,"Names")) -> 3 | I10: =INDIRECT(ADDRESS(D10+1,1,,,"Names")) -> 6 | N10: =IF(ISNA(MATCH(COLUMN()-13,$B10:$E10,0)),"",IF($K10=MATCH(COLUMN()-13,$B10:$E10,0),3,IF($L10=MATCH(COLUMN()-13,$B10:$E10,0),2,IF($M10=MATCH(COLUMN()-13,$B10:$E10,0),1," ")))) | O10: =IF(ISNA(MATCH(COLUMN()-13,$B10:$E10,0)),"",IF($K10=MATCH(COLUMN()-13,$B10:$E10,0),3,IF($L10=MATCH(COLUMN()-13,$B10:$E10,0),2,IF($M10=MATCH(COLUMN()-13,$B10:$E10,0),1," ")))) | P10: =IF(ISNA(MATCH(COLUMN()-13,$B10:$E10,0)),"",IF($K10=MATCH(COLUMN()-13,$B10:$E10,0),3,IF($L10=MATCH(COLUMN()-13,$B10:$E10,0),2,IF($M10=MATCH(COLUMN()-13,$B10:$E10,0),1," ")))) | Q10: =IF(ISNA(MATCH(COLUMN()-13,$B10:$E10,0)),"",IF($K10=MATCH(COLUMN()-13,$B10:$E10,0),3,IF($L10=MATCH(COLUMN()-13,$B10:$E10,0),2,IF($M10=MATCH(COLUMN()-13,$B10:$E10,0),1," ")))) | R10: =IF(ISNA(MATCH(COLUMN()-13,$B10:$E10,0)),"",IF($K10=MATCH(COLUMN()-13,$B10:$E10,0),3,IF($L10=MATCH(COLUMN()-13,$B10:$E10,0),2,IF($M10=MATCH(COLUMN()-13,$B10:$E10,0),1," ")))) | S10: =IF(ISNA(MATCH(COLUMN()-13,$B10:$E10,0)),"",IF($K10=MATCH(COLUMN()-13,$B10:$E10,0),3,IF($L10=MATCH(COLUMN()-13,$B10:$E10,0),2,IF($M10=MATCH(COLUMN()-13,$B10:$E10,0),1," ")))) | T10: =IF(ISNA(MATCH(COLUMN()-13,$B10:$E10,0)),"",IF($K10=MATCH(COLUMN()-13,$B10:$E10,0),3,IF($L10=MATCH(COLUMN()-13,$B10:$E10,0),2,IF($M10=MATCH(COLUMN()-13,$B10:$E10,0),1," ")))) | U10: =IF(ISNA(MATCH(COLUMN()-13,$B10:$E10,0)),"",IF($K10=MATCH(COLUMN()-13,$B10:$E10,0),3,IF($L10=MATCH(COLUMN()-13,$B10:$E10,0),2,IF($M10=MATCH(COLUMN()-13,$B10:$E10,0),1," ")))) | ... AL10: =IF(ISNA(MATCH(COLUMN()-13,$B10:$E10,0)),"",IF($K10=MATCH(COLUMN()-13,$B10:$E10,0),3,IF($L10=MATCH(COLUMN()-13,$B10:$E10,0),2,IF($M10=MATCH(COLUMN()-13,$B10:$E10,0),1," "))))
B11: 2 | C11: 4 | D11: 7 | F11: 2 | G11: =INDIRECT(ADDRESS(B11+1,1,,,"Names")) -> 2 | H11: =INDIRECT(ADDRESS(C11+1,1,,,"Names")) -> 4 | I11: =INDIRECT(ADDRESS(D11+1,1,,,"Names")) -> 7 | N11: =IF(ISNA(MATCH(COLUMN()-13,$B11:$E11,0)),"",IF($K11=MATCH(COLUMN()-13,$B11:$E11,0),3,IF($L11=MATCH(COLUMN()-13,$B11:$E11,0),2,IF($M11=MATCH(COLUMN()-13,$B11:$E11,0),1," ")))) | O11: =IF(ISNA(MATCH(COLUMN()-13,$B11:$E11,0)),"",IF($K11=MATCH(COLUMN()-13,$B11:$E11,0),3,IF($L11=MATCH(COLUMN()-13,$B11:$E11,0),2,IF($M11=MATCH(COLUMN()-13,$B11:$E11,0),1," ")))) | P11: =IF(ISNA(MATCH(COLUMN()-13,$B11:$E11,0)),"",IF($K11=MATCH(COLUMN()-13,$B11:$E11,0),3,IF($L11=MATCH(COLUMN()-13,$B11:$E11,0),2,IF($M11=MATCH(COLUMN()-13,$B11:$E11,0),1," ")))) | Q11: =IF(ISNA(MATCH(COLUMN()-13,$B11:$E11,0)),"",IF($K11=MATCH(COLUMN()-13,$B11:$E11,0),3,IF($L11=MATCH(COLUMN()-13,$B11:$E11,0),2,IF($M11=MATCH(COLUMN()-13,$B11:$E11,0),1," ")))) | R11: =IF(ISNA(MATCH(COLUMN()-13,$B11:$E11,0)),"",IF($K11=MATCH(COLUMN()-13,$B11:$E11,0),3,IF($L11=MATCH(COLUMN()-13,$B11:$E11,0),2,IF($M11=MATCH(COLUMN()-13,$B11:$E11,0),1," ")))) | S11: =IF(ISNA(MATCH(COLUMN()-13,$B11:$E11,0)),"",IF($K11=MATCH(COLUMN()-13,$B11:$E11,0),3,IF($L11=MATCH(COLUMN()-13,$B11:$E11,0),2,IF($M11=MATCH(COLUMN()-13,$B11:$E11,0),1," ")))) | T11: =IF(ISNA(MATCH(COLUMN()-13,$B11:$E11,0)),"",IF($K11=MATCH(COLUMN()-13,$B11:$E11,0),3,IF($L11=MATCH(COLUMN()-13,$B11:$E11,0),2,IF($M11=MATCH(COLUMN()-13,$B11:$E11,0),1," ")))) | U11: =IF(ISNA(MATCH(COLUMN()-13,$B11:$E11,0)),"",IF($K11=MATCH(COLUMN()-13,$B11:$E11,0),3,IF($L11=MATCH(COLUMN()-13,$B11:$E11,0),2,IF($M11=MATCH(COLUMN()-13,$B11:$E11,0),1," ")))) | ... AL11: =IF(ISNA(MATCH(COLUMN()-13,$B11:$E11,0)),"",IF($K11=MATCH(COLUMN()-13,$B11:$E11,0),3,IF($L11=MATCH(COLUMN()-13,$B11:$E11,0),2,IF($M11=MATCH(COLUMN()-13,$B11:$E11,0),1," "))))
B12: 3 | C12: 5 | D12: 8 | F12: 3 | G12: =INDIRECT(ADDRESS(B12+1,1,,,"Names")) -> 3 | H12: =INDIRECT(ADDRESS(C12+1,1,,,"Names")) -> 5 | I12: =INDIRECT(ADDRESS(D12+1,1,,,"Names")) -> 8 | N12: =IF(ISNA(MATCH(COLUMN()-13,$B12:$E12,0)),"",IF($K12=MATCH(COLUMN()-13,$B12:$E12,0),3,IF($L12=MATCH(COLUMN()-13,$B12:$E12,0),2,IF($M12=MATCH(COLUMN()-13,$B12:$E12,0),1," ")))) | O12: =IF(ISNA(MATCH(COLUMN()-13,$B12:$E12,0)),"",IF($K12=MATCH(COLUMN()-13,$B12:$E12,0),3,IF($L12=MATCH(COLUMN()-13,$B12:$E12,0),2,IF($M12=MATCH(COLUMN()-13,$B12:$E12,0),1," ")))) | P12: =IF(ISNA(MATCH(COLUMN()-13,$B12:$E12,0)),"",IF($K12=MATCH(COLUMN()-13,$B12:$E12,0),3,IF($L12=MATCH(COLUMN()-13,$B12:$E12,0),2,IF($M12=MATCH(COLUMN()-13,$B12:$E12,0),1," ")))) | Q12: =IF(ISNA(MATCH(COLUMN()-13,$B12:$E12,0)),"",IF($K12=MATCH(COLUMN()-13,$B12:$E12,0),3,IF($L12=MATCH(COLUMN()-13,$B12:$E12,0),2,IF($M12=MATCH(COLUMN()-13,$B12:$E12,0),1," ")))) | R12: =IF(ISNA(MATCH(COLUMN()-13,$B12:$E12,0)),"",IF($K12=MATCH(COLUMN()-13,$B12:$E12,0),3,IF($L12=MATCH(COLUMN()-13,$B12:$E12,0),2,IF($M12=MATCH(COLUMN()-13,$B12:$E12,0),1," ")))) | S12: =IF(ISNA(MATCH(COLUMN()-13,$B12:$E12,0)),"",IF($K12=MATCH(COLUMN()-13,$B12:$E12,0),3,IF($L12=MATCH(COLUMN()-13,$B12:$E12,0),2,IF($M12=MATCH(COLUMN()-13,$B12:$E12,0),1," ")))) | T12: =IF(ISNA(MATCH(COLUMN()-13,$B12:$E12,0)),"",IF($K12=MATCH(COLUMN()-13,$B12:$E12,0),3,IF($L12=MATCH(COLUMN()-13,$B12:$E12,0),2,IF($M12=MATCH(COLUMN()-13,$B12:$E12,0),1," ")))) | U12: =IF(ISNA(MATCH(COLUMN()-13,$B12:$E12,0)),"",IF($K12=MATCH(COLUMN()-13,$B12:$E12,0),3,IF($L12=MATCH(COLUMN()-13,$B12:$E12,0),2,IF($M12=MATCH(COLUMN()-13,$B12:$E12,0),1," ")))) | ... AL12: =IF(ISNA(MATCH(COLUMN()-13,$B12:$E12,0)),"",IF($K12=MATCH(COLUMN()-13,$B12:$E12,0),3,IF($L12=MATCH(COLUMN()-13,$B12:$E12,0),2,IF($M12=MATCH(COLUMN()-13,$B12:$E12,0),1," "))))
B13: 4 | C13: 6 | D13: 9 | F13: 4 | G13: =INDIRECT(ADDRESS(B13+1,1,,,"Names")) -> 4 | H13: =INDIRECT(ADDRESS(C13+1,1,,,"Names")) -> 6 | I13: =INDIRECT(ADDRESS(D13+1,1,,,"Names")) -> 9 | N13: =IF(ISNA(MATCH(COLUMN()-13,$B13:$E13,0)),"",IF($K13=MATCH(COLUMN()-13,$B13:$E13,0),3,IF($L13=MATCH(COLUMN()-13,$B13:$E13,0),2,IF($M13=MATCH(COLUMN()-13,$B13:$E13,0),1," ")))) | O13: =IF(ISNA(MATCH(COLUMN()-13,$B13:$E13,0)),"",IF($K13=MATCH(COLUMN()-13,$B13:$E13,0),3,IF($L13=MATCH(COLUMN()-13,$B13:$E13,0),2,IF($M13=MATCH(COLUMN()-13,$B13:$E13,0),1," ")))) | P13: =IF(ISNA(MATCH(COLUMN()-13,$B13:$E13,0)),"",IF($K13=MATCH(COLUMN()-13,$B13:$E13,0),3,IF($L13=MATCH(COLUMN()-13,$B13:$E13,0),2,IF($M13=MATCH(COLUMN()-13,$B13:$E13,0),1," ")))) | Q13: =IF(ISNA(MATCH(COLUMN()-13,$B13:$E13,0)),"",IF($K13=MATCH(COLUMN()-13,$B13:$E13,0),3,IF($L13=MATCH(COLUMN()-13,$B13:$E13,0),2,IF($M13=MATCH(COLUMN()-13,$B13:$E13,0),1," ")))) | R13: =IF(ISNA(MATCH(COLUMN()-13,$B13:$E13,0)),"",IF($K13=MATCH(COLUMN()-13,$B13:$E13,0),3,IF($L13=MATCH(COLUMN()-13,$B13:$E13,0),2,IF($M13=MATCH(COLUMN()-13,$B13:$E13,0),1," ")))) | S13: =IF(ISNA(MATCH(COLUMN()-13,$B13:$E13,0)),"",IF($K13=MATCH(COLUMN()-13,$B13:$E13,0),3,IF($L13=MATCH(COLUMN()-13,$B13:$E13,0),2,IF($M13=MATCH(COLUMN()-13,$B13:$E13,0),1," ")))) | T13: =IF(ISNA(MATCH(COLUMN()-13,$B13:$E13,0)),"",IF($K13=MATCH(COLUMN()-13,$B13:$E13,0),3,IF($L13=MATCH(COLUMN()-13,$B13:$E13,0),2,IF($M13=MATCH(COLUMN()-13,$B13:$E13,0),1," ")))) | U13: =IF(ISNA(MATCH(COLUMN()-13,$B13:$E13,0)),"",IF($K13=MATCH(COLUMN()-13,$B13:$E13,0),3,IF($L13=MATCH(COLUMN()-13,$B13:$E13,0),2,IF($M13=MATCH(COLUMN()-13,$B13:$E13,0),1," ")))) | ... AL13: =IF(ISNA(MATCH(COLUMN()-13,$B13:$E13,0)),"",IF($K13=MATCH(COLUMN()-13,$B13:$E13,0),3,IF($L13=MATCH(COLUMN()-13,$B13:$E13,0),2,IF($M13=MATCH(COLUMN()-13,$B13:$E13,0),1," "))))
B14: 5 | C14: 7 | D14: 10 | F14: 5 | G14: =INDIRECT(ADDRESS(B14+1,1,,,"Names")) -> 5 | H14: =INDIRECT(ADDRESS(C14+1,1,,,"Names")) -> 7 | I14: =INDIRECT(ADDRESS(D14+1,1,,,"Names")) -> 13 | N14: =IF(ISNA(MATCH(COLUMN()-13,$B14:$E14,0)),"",IF($K14=MATCH(COLUMN()-13,$B14:$E14,0),3,IF($L14=MATCH(COLUMN()-13,$B14:$E14,0),2,IF($M14=MATCH(COLUMN()-13,$B14:$E14,0),1," ")))) | O14: =IF(ISNA(MATCH(COLUMN()-13,$B14:$E14,0)),"",IF($K14=MATCH(COLUMN()-13,$B14:$E14,0),3,IF($L14=MATCH(COLUMN()-13,$B14:$E14,0),2,IF($M14=MATCH(COLUMN()-13,$B14:$E14,0),1," ")))) | P14: =IF(ISNA(MATCH(COLUMN()-13,$B14:$E14,0)),"",IF($K14=MATCH(COLUMN()-13,$B14:$E14,0),3,IF($L14=MATCH(COLUMN()-13,$B14:$E14,0),2,IF($M14=MATCH(COLUMN()-13,$B14:$E14,0),1," ")))) | Q14: =IF(ISNA(MATCH(COLUMN()-13,$B14:$E14,0)),"",IF($K14=MATCH(COLUMN()-13,$B14:$E14,0),3,IF($L14=MATCH(COLUMN()-13,$B14:$E14,0),2,IF($M14=MATCH(COLUMN()-13,$B14:$E14,0),1," ")))) | R14: =IF(ISNA(MATCH(COLUMN()-13,$B14:$E14,0)),"",IF($K14=MATCH(COLUMN()-13,$B14:$E14,0),3,IF($L14=MATCH(COLUMN()-13,$B14:$E14,0),2,IF($M14=MATCH(COLUMN()-13,$B14:$E14,0),1," ")))) | S14: =IF(ISNA(MATCH(COLUMN()-13,$B14:$E14,0)),"",IF($K14=MATCH(COLUMN()-13,$B14:$E14,0),3,IF($L14=MATCH(COLUMN()-13,$B14:$E14,0),2,IF($M14=MATCH(COLUMN()-13,$B14:$E14,0),1," ")))) | T14: =IF(ISNA(MATCH(COLUMN()-13,$B14:$E14,0)),"",IF($K14=MATCH(COLUMN()-13,$B14:$E14,0),3,IF($L14=MATCH(COLUMN()-13,$B14:$E14,0),2,IF($M14=MATCH(COLUMN()-13,$B14:$E14,0),1," ")))) | U14: =IF(ISNA(MATCH(COLUMN()-13,$B14:$E14,0)),"",IF($K14=MATCH(COLUMN()-13,$B14:$E14,0),3,IF($L14=MATCH(COLUMN()-13,$B14:$E14,0),2,IF($M14=MATCH(COLUMN()-13,$B14:$E14,0),1," ")))) | ... AL14: =IF(ISNA(MATCH(COLUMN()-13,$B14:$E14,0)),"",IF($K14=MATCH(COLUMN()-13,$B14:$E14,0),3,IF($L14=MATCH(COLUMN()-13,$B14:$E14,0),2,IF($M14=MATCH(COLUMN()-13,$B14:$E14,0),1," "))))
B15: 6 | C15: 8 | D15: 11 | F15: 6 | G15: =INDIRECT(ADDRESS(B15+1,1,,,"Names")) -> 6 | H15: =INDIRECT(ADDRESS(C15+1,1,,,"Names")) -> 8 | I15: =INDIRECT(ADDRESS(D15+1,1,,,"Names")) -> 14 | N15: =IF(ISNA(MATCH(COLUMN()-13,$B15:$E15,0)),"",IF($K15=MATCH(COLUMN()-13,$B15:$E15,0),3,IF($L15=MATCH(COLUMN()-13,$B15:$E15,0),2,IF($M15=MATCH(COLUMN()-13,$B15:$E15,0),1," ")))) | O15: =IF(ISNA(MATCH(COLUMN()-13,$B15:$E15,0)),"",IF($K15=MATCH(COLUMN()-13,$B15:$E15,0),3,IF($L15=MATCH(COLUMN()-13,$B15:$E15,0),2,IF($M15=MATCH(COLUMN()-13,$B15:$E15,0),1," ")))) | P15: =IF(ISNA(MATCH(COLUMN()-13,$B15:$E15,0)),"",IF($K15=MATCH(COLUMN()-13,$B15:$E15,0),3,IF($L15=MATCH(COLUMN()-13,$B15:$E15,0),2,IF($M15=MATCH(COLUMN()-13,$B15:$E15,0),1," ")))) | Q15: =IF(ISNA(MATCH(COLUMN()-13,$B15:$E15,0)),"",IF($K15=MATCH(COLUMN()-13,$B15:$E15,0),3,IF($L15=MATCH(COLUMN()-13,$B15:$E15,0),2,IF($M15=MATCH(COLUMN()-13,$B15:$E15,0),1," ")))) | R15: =IF(ISNA(MATCH(COLUMN()-13,$B15:$E15,0)),"",IF($K15=MATCH(COLUMN()-13,$B15:$E15,0),3,IF($L15=MATCH(COLUMN()-13,$B15:$E15,0),2,IF($M15=MATCH(COLUMN()-13,$B15:$E15,0),1," ")))) | S15: =IF(ISNA(MATCH(COLUMN()-13,$B15:$E15,0)),"",IF($K15=MATCH(COLUMN()-13,$B15:$E15,0),3,IF($L15=MATCH(COLUMN()-13,$B15:$E15,0),2,IF($M15=MATCH(COLUMN()-13,$B15:$E15,0),1," ")))) | T15: =IF(ISNA(MATCH(COLUMN()-13,$B15:$E15,0)),"",IF($K15=MATCH(COLUMN()-13,$B15:$E15,0),3,IF($L15=MATCH(COLUMN()-13,$B15:$E15,0),2,IF($M15=MATCH(COLUMN()-13,$B15:$E15,0),1," ")))) | U15: =IF(ISNA(MATCH(COLUMN()-13,$B15:$E15,0)),"",IF($K15=MATCH(COLUMN()-13,$B15:$E15,0),3,IF($L15=MATCH(COLUMN()-13,$B15:$E15,0),2,IF($M15=MATCH(COLUMN()-13,$B15:$E15,0),1," ")))) | ... AL15: =IF(ISNA(MATCH(COLUMN()-13,$B15:$E15,0)),"",IF($K15=MATCH(COLUMN()-13,$B15:$E15,0),3,IF($L15=MATCH(COLUMN()-13,$B15:$E15,0),2,IF($M15=MATCH(COLUMN()-13,$B15:$E15,0),1," "))))
B16: 7 | C16: 9 | D16: 12 | F16: 7 | G16: =INDIRECT(ADDRESS(B16+1,1,,,"Names")) -> 7 | H16: =INDIRECT(ADDRESS(C16+1,1,,,"Names")) -> 9 | I16: =INDIRECT(ADDRESS(D16+1,1,,,"Names")) -> 23 | N16: =IF(ISNA(MATCH(COLUMN()-13,$B16:$E16,0)),"",IF($K16=MATCH(COLUMN()-13,$B16:$E16,0),3,IF($L16=MATCH(COLUMN()-13,$B16:$E16,0),2,IF($M16=MATCH(COLUMN()-13,$B16:$E16,0),1," ")))) | O16: =IF(ISNA(MATCH(COLUMN()-13,$B16:$E16,0)),"",IF($K16=MATCH(COLUMN()-13,$B16:$E16,0),3,IF($L16=MATCH(COLUMN()-13,$B16:$E16,0),2,IF($M16=MATCH(COLUMN()-13,$B16:$E16,0),1," ")))) | P16: =IF(ISNA(MATCH(COLUMN()-13,$B16:$E16,0)),"",IF($K16=MATCH(COLUMN()-13,$B16:$E16,0),3,IF($L16=MATCH(COLUMN()-13,$B16:$E16,0),2,IF($M16=MATCH(COLUMN()-13,$B16:$E16,0),1," ")))) | Q16: =IF(ISNA(MATCH(COLUMN()-13,$B16:$E16,0)),"",IF($K16=MATCH(COLUMN()-13,$B16:$E16,0),3,IF($L16=MATCH(COLUMN()-13,$B16:$E16,0),2,IF($M16=MATCH(COLUMN()-13,$B16:$E16,0),1," ")))) | R16: =IF(ISNA(MATCH(COLUMN()-13,$B16:$E16,0)),"",IF($K16=MATCH(COLUMN()-13,$B16:$E16,0),3,IF($L16=MATCH(COLUMN()-13,$B16:$E16,0),2,IF($M16=MATCH(COLUMN()-13,$B16:$E16,0),1," ")))) | S16: =IF(ISNA(MATCH(COLUMN()-13,$B16:$E16,0)),"",IF($K16=MATCH(COLUMN()-13,$B16:$E16,0),3,IF($L16=MATCH(COLUMN()-13,$B16:$E16,0),2,IF($M16=MATCH(COLUMN()-13,$B16:$E16,0),1," ")))) | T16: =IF(ISNA(MATCH(COLUMN()-13,$B16:$E16,0)),"",IF($K16=MATCH(COLUMN()-13,$B16:$E16,0),3,IF($L16=MATCH(COLUMN()-13,$B16:$E16,0),2,IF($M16=MATCH(COLUMN()-13,$B16:$E16,0),1," ")))) | U16: =IF(ISNA(MATCH(COLUMN()-13,$B16:$E16,0)),"",IF($K16=MATCH(COLUMN()-13,$B16:$E16,0),3,IF($L16=MATCH(COLUMN()-13,$B16:$E16,0),2,IF($M16=MATCH(COLUMN()-13,$B16:$E16,0),1," ")))) | ... AL16: =IF(ISNA(MATCH(COLUMN()-13,$B16:$E16,0)),"",IF($K16=MATCH(COLUMN()-13,$B16:$E16,0),3,IF($L16=MATCH(COLUMN()-13,$B16:$E16,0),2,IF($M16=MATCH(COLUMN()-13,$B16:$E16,0),1," "))))
B17: 8 | C17: 10 | D17: 13 | F17: 8 | G17: =INDIRECT(ADDRESS(B17+1,1,,,"Names")) -> 8 | H17: =INDIRECT(ADDRESS(C17+1,1,,,"Names")) -> 13 | I17: =INDIRECT(ADDRESS(D17+1,1,,,"Names")) -> 30 | N17: =IF(ISNA(MATCH(COLUMN()-13,$B17:$E17,0)),"",IF($K17=MATCH(COLUMN()-13,$B17:$E17,0),3,IF($L17=MATCH(COLUMN()-13,$B17:$E17,0),2,IF($M17=MATCH(COLUMN()-13,$B17:$E17,0),1," ")))) | O17: =IF(ISNA(MATCH(COLUMN()-13,$B17:$E17,0)),"",IF($K17=MATCH(COLUMN()-13,$B17:$E17,0),3,IF($L17=MATCH(COLUMN()-13,$B17:$E17,0),2,IF($M17=MATCH(COLUMN()-13,$B17:$E17,0),1," ")))) | P17: =IF(ISNA(MATCH(COLUMN()-13,$B17:$E17,0)),"",IF($K17=MATCH(COLUMN()-13,$B17:$E17,0),3,IF($L17=MATCH(COLUMN()-13,$B17:$E17,0),2,IF($M17=MATCH(COLUMN()-13,$B17:$E17,0),1," ")))) | Q17: =IF(ISNA(MATCH(COLUMN()-13,$B17:$E17,0)),"",IF($K17=MATCH(COLUMN()-13,$B17:$E17,0),3,IF($L17=MATCH(COLUMN()-13,$B17:$E17,0),2,IF($M17=MATCH(COLUMN()-13,$B17:$E17,0),1," ")))) | R17: =IF(ISNA(MATCH(COLUMN()-13,$B17:$E17,0)),"",IF($K17=MATCH(COLUMN()-13,$B17:$E17,0),3,IF($L17=MATCH(COLUMN()-13,$B17:$E17,0),2,IF($M17=MATCH(COLUMN()-13,$B17:$E17,0),1," ")))) | S17: =IF(ISNA(MATCH(COLUMN()-13,$B17:$E17,0)),"",IF($K17=MATCH(COLUMN()-13,$B17:$E17,0),3,IF($L17=MATCH(COLUMN()-13,$B17:$E17,0),2,IF($M17=MATCH(COLUMN()-13,$B17:$E17,0),1," ")))) | T17: =IF(ISNA(MATCH(COLUMN()-13,$B17:$E17,0)),"",IF($K17=MATCH(COLUMN()-13,$B17:$E17,0),3,IF($L17=MATCH(COLUMN()-13,$B17:$E17,0),2,IF($M17=MATCH(COLUMN()-13,$B17:$E17,0),1," ")))) | U17: =IF(ISNA(MATCH(COLUMN()-13,$B17:$E17,0)),"",IF($K17=MATCH(COLUMN()-13,$B17:$E17,0),3,IF($L17=MATCH(COLUMN()-13,$B17:$E17,0),2,IF($M17=MATCH(COLUMN()-13,$B17:$E17,0),1," ")))) | ... AL17: =IF(ISNA(MATCH(COLUMN()-13,$B17:$E17,0)),"",IF($K17=MATCH(COLUMN()-13,$B17:$E17,0),3,IF($L17=MATCH(COLUMN()-13,$B17:$E17,0),2,IF($M17=MATCH(COLUMN()-13,$B17:$E17,0),1," "))))
B18: 9 | C18: 11 | D18: 14 | F18: 9 | G18: =INDIRECT(ADDRESS(B18+1,1,,,"Names")) -> 9 | H18: =INDIRECT(ADDRESS(C18+1,1,,,"Names")) -> 14 | I18: =INDIRECT(ADDRESS(D18+1,1,,,"Names")) -> 37 | N18: =IF(ISNA(MATCH(COLUMN()-13,$B18:$E18,0)),"",IF($K18=MATCH(COLUMN()-13,$B18:$E18,0),3,IF($L18=MATCH(COLUMN()-13,$B18:$E18,0),2,IF($M18=MATCH(COLUMN()-13,$B18:$E18,0),1," ")))) | O18: =IF(ISNA(MATCH(COLUMN()-13,$B18:$E18,0)),"",IF($K18=MATCH(COLUMN()-13,$B18:$E18,0),3,IF($L18=MATCH(COLUMN()-13,$B18:$E18,0),2,IF($M18=MATCH(COLUMN()-13,$B18:$E18,0),1," ")))) | P18: =IF(ISNA(MATCH(COLUMN()-13,$B18:$E18,0)),"",IF($K18=MATCH(COLUMN()-13,$B18:$E18,0),3,IF($L18=MATCH(COLUMN()-13,$B18:$E18,0),2,IF($M18=MATCH(COLUMN()-13,$B18:$E18,0),1," ")))) | Q18: =IF(ISNA(MATCH(COLUMN()-13,$B18:$E18,0)),"",IF($K18=MATCH(COLUMN()-13,$B18:$E18,0),3,IF($L18=MATCH(COLUMN()-13,$B18:$E18,0),2,IF($M18=MATCH(COLUMN()-13,$B18:$E18,0),1," ")))) | R18: =IF(ISNA(MATCH(COLUMN()-13,$B18:$E18,0)),"",IF($K18=MATCH(COLUMN()-13,$B18:$E18,0),3,IF($L18=MATCH(COLUMN()-13,$B18:$E18,0),2,IF($M18=MATCH(COLUMN()-13,$B18:$E18,0),1," ")))) | S18: =IF(ISNA(MATCH(COLUMN()-13,$B18:$E18,0)),"",IF($K18=MATCH(COLUMN()-13,$B18:$E18,0),3,IF($L18=MATCH(COLUMN()-13,$B18:$E18,0),2,IF($M18=MATCH(COLUMN()-13,$B18:$E18,0),1," ")))) | T18: =IF(ISNA(MATCH(COLUMN()-13,$B18:$E18,0)),"",IF($K18=MATCH(COLUMN()-13,$B18:$E18,0),3,IF($L18=MATCH(COLUMN()-13,$B18:$E18,0),2,IF($M18=MATCH(COLUMN()-13,$B18:$E18,0),1," ")))) | U18: =IF(ISNA(MATCH(COLUMN()-13,$B18:$E18,0)),"",IF($K18=MATCH(COLUMN()-13,$B18:$E18,0),3,IF($L18=MATCH(COLUMN()-13,$B18:$E18,0),2,IF($M18=MATCH(COLUMN()-13,$B18:$E18,0),1," ")))) | ... AL18: =IF(ISNA(MATCH(COLUMN()-13,$B18:$E18,0)),"",IF($K18=MATCH(COLUMN()-13,$B18:$E18,0),3,IF($L18=MATCH(COLUMN()-13,$B18:$E18,0),2,IF($M18=MATCH(COLUMN()-13,$B18:$E18,0),1," "))))
B19: 10 | C19: 12 | D19: 15 | F19: 10 | G19: =INDIRECT(ADDRESS(B19+1,1,,,"Names")) -> 13 | H19: =INDIRECT(ADDRESS(C19+1,1,,,"Names")) -> 23 | I19: =INDIRECT(ADDRESS(D19+1,1,,,"Names")) -> 49 | N19: =IF(ISNA(MATCH(COLUMN()-13,$B19:$E19,0)),"",IF($K19=MATCH(COLUMN()-13,$B19:$E19,0),3,IF($L19=MATCH(COLUMN()-13,$B19:$E19,0),2,IF($M19=MATCH(COLUMN()-13,$B19:$E19,0),1," ")))) | O19: =IF(ISNA(MATCH(COLUMN()-13,$B19:$E19,0)),"",IF($K19=MATCH(COLUMN()-13,$B19:$E19,0),3,IF($L19=MATCH(COLUMN()-13,$B19:$E19,0),2,IF($M19=MATCH(COLUMN()-13,$B19:$E19,0),1," ")))) | P19: =IF(ISNA(MATCH(COLUMN()-13,$B19:$E19,0)),"",IF($K19=MATCH(COLUMN()-13,$B19:$E19,0),3,IF($L19=MATCH(COLUMN()-13,$B19:$E19,0),2,IF($M19=MATCH(COLUMN()-13,$B19:$E19,0),1," ")))) | Q19: =IF(ISNA(MATCH(COLUMN()-13,$B19:$E19,0)),"",IF($K19=MATCH(COLUMN()-13,$B19:$E19,0),3,IF($L19=MATCH(COLUMN()-13,$B19:$E19,0),2,IF($M19=MATCH(COLUMN()-13,$B19:$E19,0),1," ")))) | R19: =IF(ISNA(MATCH(COLUMN()-13,$B19:$E19,0)),"",IF($K19=MATCH(COLUMN()-13,$B19:$E19,0),3,IF($L19=MATCH(COLUMN()-13,$B19:$E19,0),2,IF($M19=MATCH(COLUMN()-13,$B19:$E19,0),1," ")))) | S19: =IF(ISNA(MATCH(COLUMN()-13,$B19:$E19,0)),"",IF($K19=MATCH(COLUMN()-13,$B19:$E19,0),3,IF($L19=MATCH(COLUMN()-13,$B19:$E19,0),2,IF($M19=MATCH(COLUMN()-13,$B19:$E19,0),1," ")))) | T19: =IF(ISNA(MATCH(COLUMN()-13,$B19:$E19,0)),"",IF($K19=MATCH(COLUMN()-13,$B19:$E19,0),3,IF($L19=MATCH(COLUMN()-13,$B19:$E19,0),2,IF($M19=MATCH(COLUMN()-13,$B19:$E19,0),1," ")))) | U19: =IF(ISNA(MATCH(COLUMN()-13,$B19:$E19,0)),"",IF($K19=MATCH(COLUMN()-13,$B19:$E19,0),3,IF($L19=MATCH(COLUMN()-13,$B19:$E19,0),2,IF($M19=MATCH(COLUMN()-13,$B19:$E19,0),1," ")))) | ... AL19: =IF(ISNA(MATCH(COLUMN()-13,$B19:$E19,0)),"",IF($K19=MATCH(COLUMN()-13,$B19:$E19,0),3,IF($L19=MATCH(COLUMN()-13,$B19:$E19,0),2,IF($M19=MATCH(COLUMN()-13,$B19:$E19,0),1," "))))
B20: 11 | C20: 13 | D20: 16 | F20: 11 | G20: =INDIRECT(ADDRESS(B20+1,1,,,"Names")) -> 14 | H20: =INDIRECT(ADDRESS(C20+1,1,,,"Names")) -> 30 | I20: =INDIRECT(ADDRESS(D20+1,1,,,"Names")) -> 99 | N20: =IF(ISNA(MATCH(COLUMN()-13,$B20:$E20,0)),"",IF($K20=MATCH(COLUMN()-13,$B20:$E20,0),3,IF($L20=MATCH(COLUMN()-13,$B20:$E20,0),2,IF($M20=MATCH(COLUMN()-13,$B20:$E20,0),1," ")))) | O20: =IF(ISNA(MATCH(COLUMN()-13,$B20:$E20,0)),"",IF($K20=MATCH(COLUMN()-13,$B20:$E20,0),3,IF($L20=MATCH(COLUMN()-13,$B20:$E20,0),2,IF($M20=MATCH(COLUMN()-13,$B20:$E20,0),1," ")))) | P20: =IF(ISNA(MATCH(COLUMN()-13,$B20:$E20,0)),"",IF($K20=MATCH(COLUMN()-13,$B20:$E20,0),3,IF($L20=MATCH(COLUMN()-13,$B20:$E20,0),2,IF($M20=MATCH(COLUMN()-13,$B20:$E20,0),1," ")))) | Q20: =IF(ISNA(MATCH(COLUMN()-13,$B20:$E20,0)),"",IF($K20=MATCH(COLUMN()-13,$B20:$E20,0),3,IF($L20=MATCH(COLUMN()-13,$B20:$E20,0),2,IF($M20=MATCH(COLUMN()-13,$B20:$E20,0),1," ")))) | R20: =IF(ISNA(MATCH(COLUMN()-13,$B20:$E20,0)),"",IF($K20=MATCH(COLUMN()-13,$B20:$E20,0),3,IF($L20=MATCH(COLUMN()-13,$B20:$E20,0),2,IF($M20=MATCH(COLUMN()-13,$B20:$E20,0),1," ")))) | S20: =IF(ISNA(MATCH(COLUMN()-13,$B20:$E20,0)),"",IF($K20=MATCH(COLUMN()-13,$B20:$E20,0),3,IF($L20=MATCH(COLUMN()-13,$B20:$E20,0),2,IF($M20=MATCH(COLUMN()-13,$B20:$E20,0),1," ")))) | T20: =IF(ISNA(MATCH(COLUMN()-13,$B20:$E20,0)),"",IF($K20=MATCH(COLUMN()-13,$B20:$E20,0),3,IF($L20=MATCH(COLUMN()-13,$B20:$E20,0),2,IF($M20=MATCH(COLUMN()-13,$B20:$E20,0),1," ")))) | U20: =IF(ISNA(MATCH(COLUMN()-13,$B20:$E20,0)),"",IF($K20=MATCH(COLUMN()-13,$B20:$E20,0),3,IF($L20=MATCH(COLUMN()-13,$B20:$E20,0),2,IF($M20=MATCH(COLUMN()-13,$B20:$E20,0),1," ")))) | ... AL20: =IF(ISNA(MATCH(COLUMN()-13,$B20:$E20,0)),"",IF($K20=MATCH(COLUMN()-13,$B20:$E20,0),3,IF($L20=MATCH(COLUMN()-13,$B20:$E20,0),2,IF($M20=MATCH(COLUMN()-13,$B20:$E20,0),1," "))))
B21: 12 | C21: 14 | D21: 17 | F21: 12 | G21: =INDIRECT(ADDRESS(B21+1,1,,,"Names")) -> 23 | H21: =INDIRECT(ADDRESS(C21+1,1,,,"Names")) -> 37 | I21: =INDIRECT(ADDRESS(D21+1,1,,,"Names")) -> 0 | N21: =IF(ISNA(MATCH(COLUMN()-13,$B21:$E21,0)),"",IF($K21=MATCH(COLUMN()-13,$B21:$E21,0),3,IF($L21=MATCH(COLUMN()-13,$B21:$E21,0),2,IF($M21=MATCH(COLUMN()-13,$B21:$E21,0),1," ")))) | O21: =IF(ISNA(MATCH(COLUMN()-13,$B21:$E21,0)),"",IF($K21=MATCH(COLUMN()-13,$B21:$E21,0),3,IF($L21=MATCH(COLUMN()-13,$B21:$E21,0),2,IF($M21=MATCH(COLUMN()-13,$B21:$E21,0),1," ")))) | P21: =IF(ISNA(MATCH(COLUMN()-13,$B21:$E21,0)),"",IF($K21=MATCH(COLUMN()-13,$B21:$E21,0),3,IF($L21=MATCH(COLUMN()-13,$B21:$E21,0),2,IF($M21=MATCH(COLUMN()-13,$B21:$E21,0),1," ")))) | Q21: =IF(ISNA(MATCH(COLUMN()-13,$B21:$E21,0)),"",IF($K21=MATCH(COLUMN()-13,$B21:$E21,0),3,IF($L21=MATCH(COLUMN()-13,$B21:$E21,0),2,IF($M21=MATCH(COLUMN()-13,$B21:$E21,0),1," ")))) | R21: =IF(ISNA(MATCH(COLUMN()-13,$B21:$E21,0)),"",IF($K21=MATCH(COLUMN()-13,$B21:$E21,0),3,IF($L21=MATCH(COLUMN()-13,$B21:$E21,0),2,IF($M21=MATCH(COLUMN()-13,$B21:$E21,0),1," ")))) | S21: =IF(ISNA(MATCH(COLUMN()-13,$B21:$E21,0)),"",IF($K21=MATCH(COLUMN()-13,$B21:$E21,0),3,IF($L21=MATCH(COLUMN()-13,$B21:$E21,0),2,IF($M21=MATCH(COLUMN()-13,$B21:$E21,0),1," ")))) | T21: =IF(ISNA(MATCH(COLUMN()-13,$B21:$E21,0)),"",IF($K21=MATCH(COLUMN()-13,$B21:$E21,0),3,IF($L21=MATCH(COLUMN()-13,$B21:$E21,0),2,IF($M21=MATCH(COLUMN()-13,$B21:$E21,0),1," ")))) | U21: =IF(ISNA(MATCH(COLUMN()-13,$B21:$E21,0)),"",IF($K21=MATCH(COLUMN()-13,$B21:$E21,0),3,IF($L21=MATCH(COLUMN()-13,$B21:$E21,0),2,IF($M21=MATCH(COLUMN()-13,$B21:$E21,0),1," ")))) | ... AL21: =IF(ISNA(MATCH(COLUMN()-13,$B21:$E21,0)),"",IF($K21=MATCH(COLUMN()-13,$B21:$E21,0),3,IF($L21=MATCH(COLUMN()-13,$B21:$E21,0),2,IF($M21=MATCH(COLUMN()-13,$B21:$E21,0),1," "))))
... B34: 25 | C34: 2 | D34: 5 | F34: 25 | G34: =INDIRECT(ADDRESS(B34+1,1,,,"Names")) -> 0 | H34: =INDIRECT(ADDRESS(C34+1,1,,,"Names")) -> 2 | I34: =INDIRECT(ADDRESS(D34+1,1,,,"Names")) -> 5 | N34: =IF(ISNA(MATCH(COLUMN()-13,$B34:$E34,0)),"",IF($K34=MATCH(COLUMN()-13,$B34:$E34,0),3,IF($L34=MATCH(COLUMN()-13,$B34:$E34,0),2,IF($M34=MATCH(COLUMN()-13,$B34:$E34,0),1," ")))) | O34: =IF(ISNA(MATCH(COLUMN()-13,$B34:$E34,0)),"",IF($K34=MATCH(COLUMN()-13,$B34:$E34,0),3,IF($L34=MATCH(COLUMN()-13,$B34:$E34,0),2,IF($M34=MATCH(COLUMN()-13,$B34:$E34,0),1," ")))) | P34: =IF(ISNA(MATCH(COLUMN()-13,$B34:$E34,0)),"",IF($K34=MATCH(COLUMN()-13,$B34:$E34,0),3,IF($L34=MATCH(COLUMN()-13,$B34:$E34,0),2,IF($M34=MATCH(COLUMN()-13,$B34:$E34,0),1," ")))) | Q34: =IF(ISNA(MATCH(COLUMN()-13,$B34:$E34,0)),"",IF($K34=MATCH(COLUMN()-13,$B34:$E34,0),3,IF($L34=MATCH(COLUMN()-13,$B34:$E34,0),2,IF($M34=MATCH(COLUMN()-13,$B34:$E34,0),1," ")))) | R34: =IF(ISNA(MATCH(COLUMN()-13,$B34:$E34,0)),"",IF($K34=MATCH(COLUMN()-13,$B34:$E34,0),3,IF($L34=MATCH(COLUMN()-13,$B34:$E34,0),2,IF($M34=MATCH(COLUMN()-13,$B34:$E34,0),1," ")))) | S34: =IF(ISNA(MATCH(COLUMN()-13,$B34:$E34,0)),"",IF($K34=MATCH(COLUMN()-13,$B34:$E34,0),3,IF($L34=MATCH(COLUMN()-13,$B34:$E34,0),2,IF($M34=MATCH(COLUMN()-13,$B34:$E34,0),1," ")))) | T34: =IF(ISNA(MATCH(COLUMN()-13,$B34:$E34,0)),"",IF($K34=MATCH(COLUMN()-13,$B34:$E34,0),3,IF($L34=MATCH(COLUMN()-13,$B34:$E34,0),2,IF($M34=MATCH(COLUMN()-13,$B34:$E34,0),1," ")))) | U34: =IF(ISNA(MATCH(COLUMN()-13,$B34:$E34,0)),"",IF($K34=MATCH(COLUMN()-13,$B34:$E34,0),3,IF($L34=MATCH(COLUMN()-13,$B34:$E34,0),2,IF($M34=MATCH(COLUMN()-13,$B34:$E34,0),1," ")))) | ... AL34: =IF(ISNA(MATCH(COLUMN()-13,$B34:$E34,0)),"",IF($K34=MATCH(COLUMN()-13,$B34:$E34,0),3,IF($L34=MATCH(COLUMN()-13,$B34:$E34,0),2,IF($M34=MATCH(COLUMN()-13,$B34:$E34,0),1," "))))
K35: Car's Scores : | N35: =IF(SUM(N10:N29)<1," ",SUM(N10:N29)) | O35: =IF(SUM(O10:O29)<1," ",SUM(O10:O29)) | P35: =IF(SUM(P10:P29)<1," ",SUM(P10:P29)) | Q35: =IF(SUM(Q10:Q29)<1," ",SUM(Q10:Q29)) | R35: =IF(SUM(R10:R29)<1," ",SUM(R10:R29)) | S35: =IF(SUM(S10:S29)<1," ",SUM(S10:S29)) | T35: =IF(SUM(T10:T29)<1," ",SUM(T10:T29)) | U35: =IF(SUM(U10:U29)<1," ",SUM(U10:U29)) | ... AL35: =IF(SUM(AL10:AL29)<1," ",SUM(AL10:AL29))
K36: Finish Place : | N36: =RANK(N35,$N35:$AL35,0) -> #VALUE! | O36: =RANK(O35,$N35:$AL35,0) -> #VALUE! | P36: =RANK(P35,$N35:$AL35,0) -> #VALUE! | Q36: =RANK(Q35,$N35:$AL35,0) -> #VALUE! | R36: =RANK(R35,$N35:$AL35,0) -> #VALUE! | S36: =RANK(S35,$N35:$AL35,0) -> #VALUE! | T36: =RANK(T35,$N35:$AL35,0) -> #VALUE! | U36: =RANK(U35,$N35:$AL35,0) -> #VALUE! | ... AL36: =RANK(AL35,$N35:$AL35,0) -> #VALUE!
N38: =+Names!$B$2 -> Luke | O38: =+Names!$B$3 -> Ro | P38: =+Names!$B$4 -> Caleb | Q38: =+Names!$B$5 -> Zau | R38: =+Names!$B$6 -> Brady | S38: =+Names!$B$7 -> Theo | T38: =+Names!$B$8 -> Jonathan | U38: =+Names!$B$9 -> Brenton | V38: =+Names!$B$10 -> Jospe | W38: =+Names!$B$11 -> Emery | X38: =+Names!$B$12 -> Isaac | Y38: =+Names!$B$13 -> Alain | Z38: =+Names!$B$14 -> Silas | AA38: =+Names!$B$15 -> De | AB38: =+Names!$B$19 -> 0 | AC38: =+Names!$B$20 -> 0 | AD38: =+Names!$B$18 -> 0 | AE38: =+Names!#REF! -> #REF! | AF38: =+Names!#REF! -> #REF! | AG38: =+Names!$B$21 -> 0 | AH38: =+Names!$B$22 -> 0 | AI38: =+Names!$B$23 -> 0 | AJ38: =+Names!$B$24 -> 0 | AK38: =+Names!$B$25 -> 0 | AL38: =+Names!$B$26 -> 0

Sheet 24 Cars
F1: =+Banner -> Westminster Trailblazers Pinewood Derby
F2: Heat | H2: 1 | I2: =+Names!$C$1 -> Driver | M2: Finish | R2: Legend
F3: Lane 1 | H3: =INDIRECT(ADDRESS(INDIRECT(ADDRESS($H$2+9,2))+1,1,,,"Names")) -> 1 | I3: =INDIRECT(ADDRESS(INDIRECT(ADDRESS($H$2+9,2))+1,2,,,"Names")) -> Luke | M3: =IF(INDIRECT(ADDRESS(9+$H$2,11))=1,"1st",IF(INDIRECT(ADDRESS(9+$H$2,12))=1,"2nd",IF(INDIRECT(ADDRESS(9+$H$2,13))=1,"3rd"," "))) | N3: =IF($K3=4,3,IF($L3=4,2,IF($M3=4,1," "))) | S3: = 1st (3pts)
F4: Lane 2 | H4: =INDIRECT(ADDRESS(INDIRECT(ADDRESS($H$2+9,3))+1,1,,,"Names")) -> 3 | I4: =INDIRECT(ADDRESS(INDIRECT(ADDRESS($H$2+9,3))+1,2,,,"Names")) -> Caleb | M4: =IF(INDIRECT(ADDRESS(9+$H$2,11))=2,"1st",IF(INDIRECT(ADDRESS(9+$H$2,12))=2,"2nd",IF(INDIRECT(ADDRESS(9+$H$2,13))=2,"3rd"," "))) | N4: =IF($K4=4,3,IF($L4=4,2,IF($M4=4,1," "))) | S4: = 2nd (2pts)
F5: Lane 3 | H5: =INDIRECT(ADDRESS(INDIRECT(ADDRESS($H$2+9,4))+1,1,,,"Names")) -> 6 | I5: =INDIRECT(ADDRESS(INDIRECT(ADDRESS($H$2+9,4))+1,2,,,"Names")) -> Theo | M5: =IF(INDIRECT(ADDRESS(9+$H$2,11))=3,"1st",IF(INDIRECT(ADDRESS(9+$H$2,12))=3,"2nd",IF(INDIRECT(ADDRESS(9+$H$2,13))=3,"3rd"," "))) | N5: =IF($K5=4,3,IF($L5=4,2,IF($M5=4,1," "))) | S5: = 3rd (1pt)
G8: Car | K8: Lane Finish | N8: Points
F9: Heat | G9: Lane 1 | H9: Lane 2 | I9: Lane 3 | J9: Lane 4 | K9: 1st | L9: 2nd | M9: 3rd | N9: =+Names!$A$2 -> 1 | O9: =+Names!$A$3 -> 2 | P9: =+Names!$A$4 -> 3 | Q9: =+Names!$A$5 -> 4 | R9: =+Names!$A$6 -> 5 | S9: =+Names!$A$7 -> 6 | T9: =+Names!$A$8 -> 7 | U9: =+Names!$A$9 -> 8 | V9: =+Names!$A$10 -> 9 | W9: =+Names!$A$11 -> 13 | X9: =+Names!$A$12 -> 14 | Y9: =+Names!$A$13 -> 23 | Z9: =+Names!$A$14 -> 30 | AA9: =+Names!$A$15 -> 37 | AB9: =+Names!$A$16 -> 49 | AC9: =+Names!$A$17 -> 99 | AD9: =+Names!$A$18 -> 0 | AE9: =+Names!$A$19 -> 0 | AF9: =+Names!$A$20 -> 0 | AG9: =+Names!$A$21 -> 0 | AH9: =+Names!$A$22 -> 0 | AI9: =+Names!$A$23 -> 0 | AJ9: =+Names!$A$24 -> 0 | AK9: =+Names!$A$25 -> 0
B10: 1 | C10: 3 | D10: 6 | F10: 1 | G10: =INDIRECT(ADDRESS(B10+1,1,,,"Names")) -> 1 | H10: =INDIRECT(ADDRESS(C10+1,1,,,"Names")) -> 3 | I10: =INDIRECT(ADDRESS(D10+1,1,,,"Names")) -> 6 | N10: =IF(ISNA(MATCH(COLUMN()-13,$B10:$E10,0)),"",IF($K10=MATCH(COLUMN()-13,$B10:$E10,0),3,IF($L10=MATCH(COLUMN()-13,$B10:$E10,0),2,IF($M10=MATCH(COLUMN()-13,$B10:$E10,0),1," ")))) | O10: =IF(ISNA(MATCH(COLUMN()-13,$B10:$E10,0)),"",IF($K10=MATCH(COLUMN()-13,$B10:$E10,0),3,IF($L10=MATCH(COLUMN()-13,$B10:$E10,0),2,IF($M10=MATCH(COLUMN()-13,$B10:$E10,0),1," ")))) | P10: =IF(ISNA(MATCH(COLUMN()-13,$B10:$E10,0)),"",IF($K10=MATCH(COLUMN()-13,$B10:$E10,0),3,IF($L10=MATCH(COLUMN()-13,$B10:$E10,0),2,IF($M10=MATCH(COLUMN()-13,$B10:$E10,0),1," ")))) | Q10: =IF(ISNA(MATCH(COLUMN()-13,$B10:$E10,0)),"",IF($K10=MATCH(COLUMN()-13,$B10:$E10,0),3,IF($L10=MATCH(COLUMN()-13,$B10:$E10,0),2,IF($M10=MATCH(COLUMN()-13,$B10:$E10,0),1," ")))) | R10: =IF(ISNA(MATCH(COLUMN()-13,$B10:$E10,0)),"",IF($K10=MATCH(COLUMN()-13,$B10:$E10,0),3,IF($L10=MATCH(COLUMN()-13,$B10:$E10,0),2,IF($M10=MATCH(COLUMN()-13,$B10:$E10,0),1," ")))) | S10: =IF(ISNA(MATCH(COLUMN()-13,$B10:$E10,0)),"",IF($K10=MATCH(COLUMN()-13,$B10:$E10,0),3,IF($L10=MATCH(COLUMN()-13,$B10:$E10,0),2,IF($M10=MATCH(COLUMN()-13,$B10:$E10,0),1," ")))) | T10: =IF(ISNA(MATCH(COLUMN()-13,$B10:$E10,0)),"",IF($K10=MATCH(COLUMN()-13,$B10:$E10,0),3,IF($L10=MATCH(COLUMN()-13,$B10:$E10,0),2,IF($M10=MATCH(COLUMN()-13,$B10:$E10,0),1," ")))) | U10: =IF(ISNA(MATCH(COLUMN()-13,$B10:$E10,0)),"",IF($K10=MATCH(COLUMN()-13,$B10:$E10,0),3,IF($L10=MATCH(COLUMN()-13,$B10:$E10,0),2,IF($M10=MATCH(COLUMN()-13,$B10:$E10,0),1," ")))) | ... AK10: =IF(ISNA(MATCH(COLUMN()-13,$B10:$E10,0)),"",IF($K10=MATCH(COLUMN()-13,$B10:$E10,0),3,IF($L10=MATCH(COLUMN()-13,$B10:$E10,0),2,IF($M10=MATCH(COLUMN()-13,$B10:$E10,0),1," "))))
B11: 2 | C11: 4 | D11: 7 | F11: 2 | G11: =INDIRECT(ADDRESS(B11+1,1,,,"Names")) -> 2 | H11: =INDIRECT(ADDRESS(C11+1,1,,,"Names")) -> 4 | I11: =INDIRECT(ADDRESS(D11+1,1,,,"Names")) -> 7 | N11: =IF(ISNA(MATCH(COLUMN()-13,$B11:$E11,0)),"",IF($K11=MATCH(COLUMN()-13,$B11:$E11,0),3,IF($L11=MATCH(COLUMN()-13,$B11:$E11,0),2,IF($M11=MATCH(COLUMN()-13,$B11:$E11,0),1," ")))) | O11: =IF(ISNA(MATCH(COLUMN()-13,$B11:$E11,0)),"",IF($K11=MATCH(COLUMN()-13,$B11:$E11,0),3,IF($L11=MATCH(COLUMN()-13,$B11:$E11,0),2,IF($M11=MATCH(COLUMN()-13,$B11:$E11,0),1," ")))) | P11: =IF(ISNA(MATCH(COLUMN()-13,$B11:$E11,0)),"",IF($K11=MATCH(COLUMN()-13,$B11:$E11,0),3,IF($L11=MATCH(COLUMN()-13,$B11:$E11,0),2,IF($M11=MATCH(COLUMN()-13,$B11:$E11,0),1," ")))) | Q11: =IF(ISNA(MATCH(COLUMN()-13,$B11:$E11,0)),"",IF($K11=MATCH(COLUMN()-13,$B11:$E11,0),3,IF($L11=MATCH(COLUMN()-13,$B11:$E11,0),2,IF($M11=MATCH(COLUMN()-13,$B11:$E11,0),1," ")))) | R11: =IF(ISNA(MATCH(COLUMN()-13,$B11:$E11,0)),"",IF($K11=MATCH(COLUMN()-13,$B11:$E11,0),3,IF($L11=MATCH(COLUMN()-13,$B11:$E11,0),2,IF($M11=MATCH(COLUMN()-13,$B11:$E11,0),1," ")))) | S11: =IF(ISNA(MATCH(COLUMN()-13,$B11:$E11,0)),"",IF($K11=MATCH(COLUMN()-13,$B11:$E11,0),3,IF($L11=MATCH(COLUMN()-13,$B11:$E11,0),2,IF($M11=MATCH(COLUMN()-13,$B11:$E11,0),1," ")))) | T11: =IF(ISNA(MATCH(COLUMN()-13,$B11:$E11,0)),"",IF($K11=MATCH(COLUMN()-13,$B11:$E11,0),3,IF($L11=MATCH(COLUMN()-13,$B11:$E11,0),2,IF($M11=MATCH(COLUMN()-13,$B11:$E11,0),1," ")))) | U11: =IF(ISNA(MATCH(COLUMN()-13,$B11:$E11,0)),"",IF($K11=MATCH(COLUMN()-13,$B11:$E11,0),3,IF($L11=MATCH(COLUMN()-13,$B11:$E11,0),2,IF($M11=MATCH(COLUMN()-13,$B11:$E11,0),1," ")))) | ... AK11: =IF(ISNA(MATCH(COLUMN()-13,$B11:$E11,0)),"",IF($K11=MATCH(COLUMN()-13,$B11:$E11,0),3,IF($L11=MATCH(COLUMN()-13,$B11:$E11,0),2,IF($M11=MATCH(COLUMN()-13,$B11:$E11,0),1," "))))
B12: 3 | C12: 5 | D12: 8 | F12: 3 | G12: =INDIRECT(ADDRESS(B12+1,1,,,"Names")) -> 3 | H12: =INDIRECT(ADDRESS(C12+1,1,,,"Names")) -> 5 | I12: =INDIRECT(ADDRESS(D12+1,1,,,"Names")) -> 8 | N12: =IF(ISNA(MATCH(COLUMN()-13,$B12:$E12,0)),"",IF($K12=MATCH(COLUMN()-13,$B12:$E12,0),3,IF($L12=MATCH(COLUMN()-13,$B12:$E12,0),2,IF($M12=MATCH(COLUMN()-13,$B12:$E12,0),1," ")))) | O12: =IF(ISNA(MATCH(COLUMN()-13,$B12:$E12,0)),"",IF($K12=MATCH(COLUMN()-13,$B12:$E12,0),3,IF($L12=MATCH(COLUMN()-13,$B12:$E12,0),2,IF($M12=MATCH(COLUMN()-13,$B12:$E12,0),1," ")))) | P12: =IF(ISNA(MATCH(COLUMN()-13,$B12:$E12,0)),"",IF($K12=MATCH(COLUMN()-13,$B12:$E12,0),3,IF($L12=MATCH(COLUMN()-13,$B12:$E12,0),2,IF($M12=MATCH(COLUMN()-13,$B12:$E12,0),1," ")))) | Q12: =IF(ISNA(MATCH(COLUMN()-13,$B12:$E12,0)),"",IF($K12=MATCH(COLUMN()-13,$B12:$E12,0),3,IF($L12=MATCH(COLUMN()-13,$B12:$E12,0),2,IF($M12=MATCH(COLUMN()-13,$B12:$E12,0),1," ")))) | R12: =IF(ISNA(MATCH(COLUMN()-13,$B12:$E12,0)),"",IF($K12=MATCH(COLUMN()-13,$B12:$E12,0),3,IF($L12=MATCH(COLUMN()-13,$B12:$E12,0),2,IF($M12=MATCH(COLUMN()-13,$B12:$E12,0),1," ")))) | S12: =IF(ISNA(MATCH(COLUMN()-13,$B12:$E12,0)),"",IF($K12=MATCH(COLUMN()-13,$B12:$E12,0),3,IF($L12=MATCH(COLUMN()-13,$B12:$E12,0),2,IF($M12=MATCH(COLUMN()-13,$B12:$E12,0),1," ")))) | T12: =IF(ISNA(MATCH(COLUMN()-13,$B12:$E12,0)),"",IF($K12=MATCH(COLUMN()-13,$B12:$E12,0),3,IF($L12=MATCH(COLUMN()-13,$B12:$E12,0),2,IF($M12=MATCH(COLUMN()-13,$B12:$E12,0),1," ")))) | U12: =IF(ISNA(MATCH(COLUMN()-13,$B12:$E12,0)),"",IF($K12=MATCH(COLUMN()-13,$B12:$E12,0),3,IF($L12=MATCH(COLUMN()-13,$B12:$E12,0),2,IF($M12=MATCH(COLUMN()-13,$B12:$E12,0),1," ")))) | ... AK12: =IF(ISNA(MATCH(COLUMN()-13,$B12:$E12,0)),"",IF($K12=MATCH(COLUMN()-13,$B12:$E12,0),3,IF($L12=MATCH(COLUMN()-13,$B12:$E12,0),2,IF($M12=MATCH(COLUMN()-13,$B12:$E12,0),1," "))))
B13: 4 | C13: 6 | D13: 9 | F13: 4 | G13: =INDIRECT(ADDRESS(B13+1,1,,,"Names")) -> 4 | H13: =INDIRECT(ADDRESS(C13+1,1,,,"Names")) -> 6 | I13: =INDIRECT(ADDRESS(D13+1,1,,,"Names")) -> 9 | N13: =IF(ISNA(MATCH(COLUMN()-13,$B13:$E13,0)),"",IF($K13=MATCH(COLUMN()-13,$B13:$E13,0),3,IF($L13=MATCH(COLUMN()-13,$B13:$E13,0),2,IF($M13=MATCH(COLUMN()-13,$B13:$E13,0),1," ")))) | O13: =IF(ISNA(MATCH(COLUMN()-13,$B13:$E13,0)),"",IF($K13=MATCH(COLUMN()-13,$B13:$E13,0),3,IF($L13=MATCH(COLUMN()-13,$B13:$E13,0),2,IF($M13=MATCH(COLUMN()-13,$B13:$E13,0),1," ")))) | P13: =IF(ISNA(MATCH(COLUMN()-13,$B13:$E13,0)),"",IF($K13=MATCH(COLUMN()-13,$B13:$E13,0),3,IF($L13=MATCH(COLUMN()-13,$B13:$E13,0),2,IF($M13=MATCH(COLUMN()-13,$B13:$E13,0),1," ")))) | Q13: =IF(ISNA(MATCH(COLUMN()-13,$B13:$E13,0)),"",IF($K13=MATCH(COLUMN()-13,$B13:$E13,0),3,IF($L13=MATCH(COLUMN()-13,$B13:$E13,0),2,IF($M13=MATCH(COLUMN()-13,$B13:$E13,0),1," ")))) | R13: =IF(ISNA(MATCH(COLUMN()-13,$B13:$E13,0)),"",IF($K13=MATCH(COLUMN()-13,$B13:$E13,0),3,IF($L13=MATCH(COLUMN()-13,$B13:$E13,0),2,IF($M13=MATCH(COLUMN()-13,$B13:$E13,0),1," ")))) | S13: =IF(ISNA(MATCH(COLUMN()-13,$B13:$E13,0)),"",IF($K13=MATCH(COLUMN()-13,$B13:$E13,0),3,IF($L13=MATCH(COLUMN()-13,$B13:$E13,0),2,IF($M13=MATCH(COLUMN()-13,$B13:$E13,0),1," ")))) | T13: =IF(ISNA(MATCH(COLUMN()-13,$B13:$E13,0)),"",IF($K13=MATCH(COLUMN()-13,$B13:$E13,0),3,IF($L13=MATCH(COLUMN()-13,$B13:$E13,0),2,IF($M13=MATCH(COLUMN()-13,$B13:$E13,0),1," ")))) | U13: =IF(ISNA(MATCH(COLUMN()-13,$B13:$E13,0)),"",IF($K13=MATCH(COLUMN()-13,$B13:$E13,0),3,IF($L13=MATCH(COLUMN()-13,$B13:$E13,0),2,IF($M13=MATCH(COLUMN()-13,$B13:$E13,0),1," ")))) | ... AK13: =IF(ISNA(MATCH(COLUMN()-13,$B13:$E13,0)),"",IF($K13=MATCH(COLUMN()-13,$B13:$E13,0),3,IF($L13=MATCH(COLUMN()-13,$B13:$E13,0),2,IF($M13=MATCH(COLUMN()-13,$B13:$E13,0),1," "))))
B14: 5 | C14: 7 | D14: 10 | F14: 5 | G14: =INDIRECT(ADDRESS(B14+1,1,,,"Names")) -> 5 | H14: =INDIRECT(ADDRESS(C14+1,1,,,"Names")) -> 7 | I14: =INDIRECT(ADDRESS(D14+1,1,,,"Names")) -> 13 | N14: =IF(ISNA(MATCH(COLUMN()-13,$B14:$E14,0)),"",IF($K14=MATCH(COLUMN()-13,$B14:$E14,0),3,IF($L14=MATCH(COLUMN()-13,$B14:$E14,0),2,IF($M14=MATCH(COLUMN()-13,$B14:$E14,0),1," ")))) | O14: =IF(ISNA(MATCH(COLUMN()-13,$B14:$E14,0)),"",IF($K14=MATCH(COLUMN()-13,$B14:$E14,0),3,IF($L14=MATCH(COLUMN()-13,$B14:$E14,0),2,IF($M14=MATCH(COLUMN()-13,$B14:$E14,0),1," ")))) | P14: =IF(ISNA(MATCH(COLUMN()-13,$B14:$E14,0)),"",IF($K14=MATCH(COLUMN()-13,$B14:$E14,0),3,IF($L14=MATCH(COLUMN()-13,$B14:$E14,0),2,IF($M14=MATCH(COLUMN()-13,$B14:$E14,0),1," ")))) | Q14: =IF(ISNA(MATCH(COLUMN()-13,$B14:$E14,0)),"",IF($K14=MATCH(COLUMN()-13,$B14:$E14,0),3,IF($L14=MATCH(COLUMN()-13,$B14:$E14,0),2,IF($M14=MATCH(COLUMN()-13,$B14:$E14,0),1," ")))) | R14: =IF(ISNA(MATCH(COLUMN()-13,$B14:$E14,0)),"",IF($K14=MATCH(COLUMN()-13,$B14:$E14,0),3,IF($L14=MATCH(COLUMN()-13,$B14:$E14,0),2,IF($M14=MATCH(COLUMN()-13,$B14:$E14,0),1," ")))) | S14: =IF(ISNA(MATCH(COLUMN()-13,$B14:$E14,0)),"",IF($K14=MATCH(COLUMN()-13,$B14:$E14,0),3,IF($L14=MATCH(COLUMN()-13,$B14:$E14,0),2,IF($M14=MATCH(COLUMN()-13,$B14:$E14,0),1," ")))) | T14: =IF(ISNA(MATCH(COLUMN()-13,$B14:$E14,0)),"",IF($K14=MATCH(COLUMN()-13,$B14:$E14,0),3,IF($L14=MATCH(COLUMN()-13,$B14:$E14,0),2,IF($M14=MATCH(COLUMN()-13,$B14:$E14,0),1," ")))) | U14: =IF(ISNA(MATCH(COLUMN()-13,$B14:$E14,0)),"",IF($K14=MATCH(COLUMN()-13,$B14:$E14,0),3,IF($L14=MATCH(COLUMN()-13,$B14:$E14,0),2,IF($M14=MATCH(COLUMN()-13,$B14:$E14,0),1," ")))) | ... AK14: =IF(ISNA(MATCH(COLUMN()-13,$B14:$E14,0)),"",IF($K14=MATCH(COLUMN()-13,$B14:$E14,0),3,IF($L14=MATCH(COLUMN()-13,$B14:$E14,0),2,IF($M14=MATCH(COLUMN()-13,$B14:$E14,0),1," "))))
B15: 6 | C15: 8 | D15: 11 | F15: 6 | G15: =INDIRECT(ADDRESS(B15+1,1,,,"Names")) -> 6 | H15: =INDIRECT(ADDRESS(C15+1,1,,,"Names")) -> 8 | I15: =INDIRECT(ADDRESS(D15+1,1,,,"Names")) -> 14 | N15: =IF(ISNA(MATCH(COLUMN()-13,$B15:$E15,0)),"",IF($K15=MATCH(COLUMN()-13,$B15:$E15,0),3,IF($L15=MATCH(COLUMN()-13,$B15:$E15,0),2,IF($M15=MATCH(COLUMN()-13,$B15:$E15,0),1," ")))) | O15: =IF(ISNA(MATCH(COLUMN()-13,$B15:$E15,0)),"",IF($K15=MATCH(COLUMN()-13,$B15:$E15,0),3,IF($L15=MATCH(COLUMN()-13,$B15:$E15,0),2,IF($M15=MATCH(COLUMN()-13,$B15:$E15,0),1," ")))) | P15: =IF(ISNA(MATCH(COLUMN()-13,$B15:$E15,0)),"",IF($K15=MATCH(COLUMN()-13,$B15:$E15,0),3,IF($L15=MATCH(COLUMN()-13,$B15:$E15,0),2,IF($M15=MATCH(COLUMN()-13,$B15:$E15,0),1," ")))) | Q15: =IF(ISNA(MATCH(COLUMN()-13,$B15:$E15,0)),"",IF($K15=MATCH(COLUMN()-13,$B15:$E15,0),3,IF($L15=MATCH(COLUMN()-13,$B15:$E15,0),2,IF($M15=MATCH(COLUMN()-13,$B15:$E15,0),1," ")))) | R15: =IF(ISNA(MATCH(COLUMN()-13,$B15:$E15,0)),"",IF($K15=MATCH(COLUMN()-13,$B15:$E15,0),3,IF($L15=MATCH(COLUMN()-13,$B15:$E15,0),2,IF($M15=MATCH(COLUMN()-13,$B15:$E15,0),1," ")))) | S15: =IF(ISNA(MATCH(COLUMN()-13,$B15:$E15,0)),"",IF($K15=MATCH(COLUMN()-13,$B15:$E15,0),3,IF($L15=MATCH(COLUMN()-13,$B15:$E15,0),2,IF($M15=MATCH(COLUMN()-13,$B15:$E15,0),1," ")))) | T15: =IF(ISNA(MATCH(COLUMN()-13,$B15:$E15,0)),"",IF($K15=MATCH(COLUMN()-13,$B15:$E15,0),3,IF($L15=MATCH(COLUMN()-13,$B15:$E15,0),2,IF($M15=MATCH(COLUMN()-13,$B15:$E15,0),1," ")))) | U15: =IF(ISNA(MATCH(COLUMN()-13,$B15:$E15,0)),"",IF($K15=MATCH(COLUMN()-13,$B15:$E15,0),3,IF($L15=MATCH(COLUMN()-13,$B15:$E15,0),2,IF($M15=MATCH(COLUMN()-13,$B15:$E15,0),1," ")))) | ... AK15: =IF(ISNA(MATCH(COLUMN()-13,$B15:$E15,0)),"",IF($K15=MATCH(COLUMN()-13,$B15:$E15,0),3,IF($L15=MATCH(COLUMN()-13,$B15:$E15,0),2,IF($M15=MATCH(COLUMN()-13,$B15:$E15,0),1," "))))
B16: 7 | C16: 9 | D16: 12 | F16: 7 | G16: =INDIRECT(ADDRESS(B16+1,1,,,"Names")) -> 7 | H16: =INDIRECT(ADDRESS(C16+1,1,,,"Names")) -> 9 | I16: =INDIRECT(ADDRESS(D16+1,1,,,"Names")) -> 23 | N16: =IF(ISNA(MATCH(COLUMN()-13,$B16:$E16,0)),"",IF($K16=MATCH(COLUMN()-13,$B16:$E16,0),3,IF($L16=MATCH(COLUMN()-13,$B16:$E16,0),2,IF($M16=MATCH(COLUMN()-13,$B16:$E16,0),1," ")))) | O16: =IF(ISNA(MATCH(COLUMN()-13,$B16:$E16,0)),"",IF($K16=MATCH(COLUMN()-13,$B16:$E16,0),3,IF($L16=MATCH(COLUMN()-13,$B16:$E16,0),2,IF($M16=MATCH(COLUMN()-13,$B16:$E16,0),1," ")))) | P16: =IF(ISNA(MATCH(COLUMN()-13,$B16:$E16,0)),"",IF($K16=MATCH(COLUMN()-13,$B16:$E16,0),3,IF($L16=MATCH(COLUMN()-13,$B16:$E16,0),2,IF($M16=MATCH(COLUMN()-13,$B16:$E16,0),1," ")))) | Q16: =IF(ISNA(MATCH(COLUMN()-13,$B16:$E16,0)),"",IF($K16=MATCH(COLUMN()-13,$B16:$E16,0),3,IF($L16=MATCH(COLUMN()-13,$B16:$E16,0),2,IF($M16=MATCH(COLUMN()-13,$B16:$E16,0),1," ")))) | R16: =IF(ISNA(MATCH(COLUMN()-13,$B16:$E16,0)),"",IF($K16=MATCH(COLUMN()-13,$B16:$E16,0),3,IF($L16=MATCH(COLUMN()-13,$B16:$E16,0),2,IF($M16=MATCH(COLUMN()-13,$B16:$E16,0),1," ")))) | S16: =IF(ISNA(MATCH(COLUMN()-13,$B16:$E16,0)),"",IF($K16=MATCH(COLUMN()-13,$B16:$E16,0),3,IF($L16=MATCH(COLUMN()-13,$B16:$E16,0),2,IF($M16=MATCH(COLUMN()-13,$B16:$E16,0),1," ")))) | T16: =IF(ISNA(MATCH(COLUMN()-13,$B16:$E16,0)),"",IF($K16=MATCH(COLUMN()-13,$B16:$E16,0),3,IF($L16=MATCH(COLUMN()-13,$B16:$E16,0),2,IF($M16=MATCH(COLUMN()-13,$B16:$E16,0),1," ")))) | U16: =IF(ISNA(MATCH(COLUMN()-13,$B16:$E16,0)),"",IF($K16=MATCH(COLUMN()-13,$B16:$E16,0),3,IF($L16=MATCH(COLUMN()-13,$B16:$E16,0),2,IF($M16=MATCH(COLUMN()-13,$B16:$E16,0),1," ")))) | ... AK16: =IF(ISNA(MATCH(COLUMN()-13,$B16:$E16,0)),"",IF($K16=MATCH(COLUMN()-13,$B16:$E16,0),3,IF($L16=MATCH(COLUMN()-13,$B16:$E16,0),2,IF($M16=MATCH(COLUMN()-13,$B16:$E16,0),1," "))))
B17: 8 | C17: 10 | D17: 13 | F17: 8 | G17: =INDIRECT(ADDRESS(B17+1,1,,,"Names")) -> 8 | H17: =INDIRECT(ADDRESS(C17+1,1,,,"Names")) -> 13 | I17: =INDIRECT(ADDRESS(D17+1,1,,,"Names")) -> 30 | N17: =IF(ISNA(MATCH(COLUMN()-13,$B17:$E17,0)),"",IF($K17=MATCH(COLUMN()-13,$B17:$E17,0),3,IF($L17=MATCH(COLUMN()-13,$B17:$E17,0),2,IF($M17=MATCH(COLUMN()-13,$B17:$E17,0),1," ")))) | O17: =IF(ISNA(MATCH(COLUMN()-13,$B17:$E17,0)),"",IF($K17=MATCH(COLUMN()-13,$B17:$E17,0),3,IF($L17=MATCH(COLUMN()-13,$B17:$E17,0),2,IF($M17=MATCH(COLUMN()-13,$B17:$E17,0),1," ")))) | P17: =IF(ISNA(MATCH(COLUMN()-13,$B17:$E17,0)),"",IF($K17=MATCH(COLUMN()-13,$B17:$E17,0),3,IF($L17=MATCH(COLUMN()-13,$B17:$E17,0),2,IF($M17=MATCH(COLUMN()-13,$B17:$E17,0),1," ")))) | Q17: =IF(ISNA(MATCH(COLUMN()-13,$B17:$E17,0)),"",IF($K17=MATCH(COLUMN()-13,$B17:$E17,0),3,IF($L17=MATCH(COLUMN()-13,$B17:$E17,0),2,IF($M17=MATCH(COLUMN()-13,$B17:$E17,0),1," ")))) | R17: =IF(ISNA(MATCH(COLUMN()-13,$B17:$E17,0)),"",IF($K17=MATCH(COLUMN()-13,$B17:$E17,0),3,IF($L17=MATCH(COLUMN()-13,$B17:$E17,0),2,IF($M17=MATCH(COLUMN()-13,$B17:$E17,0),1," ")))) | S17: =IF(ISNA(MATCH(COLUMN()-13,$B17:$E17,0)),"",IF($K17=MATCH(COLUMN()-13,$B17:$E17,0),3,IF($L17=MATCH(COLUMN()-13,$B17:$E17,0),2,IF($M17=MATCH(COLUMN()-13,$B17:$E17,0),1," ")))) | T17: =IF(ISNA(MATCH(COLUMN()-13,$B17:$E17,0)),"",IF($K17=MATCH(COLUMN()-13,$B17:$E17,0),3,IF($L17=MATCH(COLUMN()-13,$B17:$E17,0),2,IF($M17=MATCH(COLUMN()-13,$B17:$E17,0),1," ")))) | U17: =IF(ISNA(MATCH(COLUMN()-13,$B17:$E17,0)),"",IF($K17=MATCH(COLUMN()-13,$B17:$E17,0),3,IF($L17=MATCH(COLUMN()-13,$B17:$E17,0),2,IF($M17=MATCH(COLUMN()-13,$B17:$E17,0),1," ")))) | ... AK17: =IF(ISNA(MATCH(COLUMN()-13,$B17:$E17,0)),"",IF($K17=MATCH(COLUMN()-13,$B17:$E17,0),3,IF($L17=MATCH(COLUMN()-13,$B17:$E17,0),2,IF($M17=MATCH(COLUMN()-13,$B17:$E17,0),1," "))))
B18: 9 | C18: 11 | D18: 14 | F18: 9 | G18: =INDIRECT(ADDRESS(B18+1,1,,,"Names")) -> 9 | H18: =INDIRECT(ADDRESS(C18+1,1,,,"Names")) -> 14 | I18: =INDIRECT(ADDRESS(D18+1,1,,,"Names")) -> 37 | N18: =IF(ISNA(MATCH(COLUMN()-13,$B18:$E18,0)),"",IF($K18=MATCH(COLUMN()-13,$B18:$E18,0),3,IF($L18=MATCH(COLUMN()-13,$B18:$E18,0),2,IF($M18=MATCH(COLUMN()-13,$B18:$E18,0),1," ")))) | O18: =IF(ISNA(MATCH(COLUMN()-13,$B18:$E18,0)),"",IF($K18=MATCH(COLUMN()-13,$B18:$E18,0),3,IF($L18=MATCH(COLUMN()-13,$B18:$E18,0),2,IF($M18=MATCH(COLUMN()-13,$B18:$E18,0),1," ")))) | P18: =IF(ISNA(MATCH(COLUMN()-13,$B18:$E18,0)),"",IF($K18=MATCH(COLUMN()-13,$B18:$E18,0),3,IF($L18=MATCH(COLUMN()-13,$B18:$E18,0),2,IF($M18=MATCH(COLUMN()-13,$B18:$E18,0),1," ")))) | Q18: =IF(ISNA(MATCH(COLUMN()-13,$B18:$E18,0)),"",IF($K18=MATCH(COLUMN()-13,$B18:$E18,0),3,IF($L18=MATCH(COLUMN()-13,$B18:$E18,0),2,IF($M18=MATCH(COLUMN()-13,$B18:$E18,0),1," ")))) | R18: =IF(ISNA(MATCH(COLUMN()-13,$B18:$E18,0)),"",IF($K18=MATCH(COLUMN()-13,$B18:$E18,0),3,IF($L18=MATCH(COLUMN()-13,$B18:$E18,0),2,IF($M18=MATCH(COLUMN()-13,$B18:$E18,0),1," ")))) | S18: =IF(ISNA(MATCH(COLUMN()-13,$B18:$E18,0)),"",IF($K18=MATCH(COLUMN()-13,$B18:$E18,0),3,IF($L18=MATCH(COLUMN()-13,$B18:$E18,0),2,IF($M18=MATCH(COLUMN()-13,$B18:$E18,0),1," ")))) | T18: =IF(ISNA(MATCH(COLUMN()-13,$B18:$E18,0)),"",IF($K18=MATCH(COLUMN()-13,$B18:$E18,0),3,IF($L18=MATCH(COLUMN()-13,$B18:$E18,0),2,IF($M18=MATCH(COLUMN()-13,$B18:$E18,0),1," ")))) | U18: =IF(ISNA(MATCH(COLUMN()-13,$B18:$E18,0)),"",IF($K18=MATCH(COLUMN()-13,$B18:$E18,0),3,IF($L18=MATCH(COLUMN()-13,$B18:$E18,0),2,IF($M18=MATCH(COLUMN()-13,$B18:$E18,0),1," ")))) | ... AK18: =IF(ISNA(MATCH(COLUMN()-13,$B18:$E18,0)),"",IF($K18=MATCH(COLUMN()-13,$B18:$E18,0),3,IF($L18=MATCH(COLUMN()-13,$B18:$E18,0),2,IF($M18=MATCH(COLUMN()-13,$B18:$E18,0),1," "))))
B19: 10 | C19: 12 | D19: 15 | F19: 10 | G19: =INDIRECT(ADDRESS(B19+1,1,,,"Names")) -> 13 | H19: =INDIRECT(ADDRESS(C19+1,1,,,"Names")) -> 23 | I19: =INDIRECT(ADDRESS(D19+1,1,,,"Names")) -> 49 | N19: =IF(ISNA(MATCH(COLUMN()-13,$B19:$E19,0)),"",IF($K19=MATCH(COLUMN()-13,$B19:$E19,0),3,IF($L19=MATCH(COLUMN()-13,$B19:$E19,0),2,IF($M19=MATCH(COLUMN()-13,$B19:$E19,0),1," ")))) | O19: =IF(ISNA(MATCH(COLUMN()-13,$B19:$E19,0)),"",IF($K19=MATCH(COLUMN()-13,$B19:$E19,0),3,IF($L19=MATCH(COLUMN()-13,$B19:$E19,0),2,IF($M19=MATCH(COLUMN()-13,$B19:$E19,0),1," ")))) | P19: =IF(ISNA(MATCH(COLUMN()-13,$B19:$E19,0)),"",IF($K19=MATCH(COLUMN()-13,$B19:$E19,0),3,IF($L19=MATCH(COLUMN()-13,$B19:$E19,0),2,IF($M19=MATCH(COLUMN()-13,$B19:$E19,0),1," ")))) | Q19: =IF(ISNA(MATCH(COLUMN()-13,$B19:$E19,0)),"",IF($K19=MATCH(COLUMN()-13,$B19:$E19,0),3,IF($L19=MATCH(COLUMN()-13,$B19:$E19,0),2,IF($M19=MATCH(COLUMN()-13,$B19:$E19,0),1," ")))) | R19: =IF(ISNA(MATCH(COLUMN()-13,$B19:$E19,0)),"",IF($K19=MATCH(COLUMN()-13,$B19:$E19,0),3,IF($L19=MATCH(COLUMN()-13,$B19:$E19,0),2,IF($M19=MATCH(COLUMN()-13,$B19:$E19,0),1," ")))) | S19: =IF(ISNA(MATCH(COLUMN()-13,$B19:$E19,0)),"",IF($K19=MATCH(COLUMN()-13,$B19:$E19,0),3,IF($L19=MATCH(COLUMN()-13,$B19:$E19,0),2,IF($M19=MATCH(COLUMN()-13,$B19:$E19,0),1," ")))) | T19: =IF(ISNA(MATCH(COLUMN()-13,$B19:$E19,0)),"",IF($K19=MATCH(COLUMN()-13,$B19:$E19,0),3,IF($L19=MATCH(COLUMN()-13,$B19:$E19,0),2,IF($M19=MATCH(COLUMN()-13,$B19:$E19,0),1," ")))) | U19: =IF(ISNA(MATCH(COLUMN()-13,$B19:$E19,0)),"",IF($K19=MATCH(COLUMN()-13,$B19:$E19,0),3,IF($L19=MATCH(COLUMN()-13,$B19:$E19,0),2,IF($M19=MATCH(COLUMN()-13,$B19:$E19,0),1," ")))) | ... AK19: =IF(ISNA(MATCH(COLUMN()-13,$B19:$E19,0)),"",IF($K19=MATCH(COLUMN()-13,$B19:$E19,0),3,IF($L19=MATCH(COLUMN()-13,$B19:$E19,0),2,IF($M19=MATCH(COLUMN()-13,$B19:$E19,0),1," "))))
B20: 11 | C20: 13 | D20: 16 | F20: 11 | G20: =INDIRECT(ADDRESS(B20+1,1,,,"Names")) -> 14 | H20: =INDIRECT(ADDRESS(C20+1,1,,,"Names")) -> 30 | I20: =INDIRECT(ADDRESS(D20+1,1,,,"Names")) -> 99 | N20: =IF(ISNA(MATCH(COLUMN()-13,$B20:$E20,0)),"",IF($K20=MATCH(COLUMN()-13,$B20:$E20,0),3,IF($L20=MATCH(COLUMN()-13,$B20:$E20,0),2,IF($M20=MATCH(COLUMN()-13,$B20:$E20,0),1," ")))) | O20: =IF(ISNA(MATCH(COLUMN()-13,$B20:$E20,0)),"",IF($K20=MATCH(COLUMN()-13,$B20:$E20,0),3,IF($L20=MATCH(COLUMN()-13,$B20:$E20,0),2,IF($M20=MATCH(COLUMN()-13,$B20:$E20,0),1," ")))) | P20: =IF(ISNA(MATCH(COLUMN()-13,$B20:$E20,0)),"",IF($K20=MATCH(COLUMN()-13,$B20:$E20,0),3,IF($L20=MATCH(COLUMN()-13,$B20:$E20,0),2,IF($M20=MATCH(COLUMN()-13,$B20:$E20,0),1," ")))) | Q20: =IF(ISNA(MATCH(COLUMN()-13,$B20:$E20,0)),"",IF($K20=MATCH(COLUMN()-13,$B20:$E20,0),3,IF($L20=MATCH(COLUMN()-13,$B20:$E20,0),2,IF($M20=MATCH(COLUMN()-13,$B20:$E20,0),1," ")))) | R20: =IF(ISNA(MATCH(COLUMN()-13,$B20:$E20,0)),"",IF($K20=MATCH(COLUMN()-13,$B20:$E20,0),3,IF($L20=MATCH(COLUMN()-13,$B20:$E20,0),2,IF($M20=MATCH(COLUMN()-13,$B20:$E20,0),1," ")))) | S20: =IF(ISNA(MATCH(COLUMN()-13,$B20:$E20,0)),"",IF($K20=MATCH(COLUMN()-13,$B20:$E20,0),3,IF($L20=MATCH(COLUMN()-13,$B20:$E20,0),2,IF($M20=MATCH(COLUMN()-13,$B20:$E20,0),1," ")))) | T20: =IF(ISNA(MATCH(COLUMN()-13,$B20:$E20,0)),"",IF($K20=MATCH(COLUMN()-13,$B20:$E20,0),3,IF($L20=MATCH(COLUMN()-13,$B20:$E20,0),2,IF($M20=MATCH(COLUMN()-13,$B20:$E20,0),1," ")))) | U20: =IF(ISNA(MATCH(COLUMN()-13,$B20:$E20,0)),"",IF($K20=MATCH(COLUMN()-13,$B20:$E20,0),3,IF($L20=MATCH(COLUMN()-13,$B20:$E20,0),2,IF($M20=MATCH(COLUMN()-13,$B20:$E20,0),1," ")))) | ... AK20: =IF(ISNA(MATCH(COLUMN()-13,$B20:$E20,0)),"",IF($K20=MATCH(COLUMN()-13,$B20:$E20,0),3,IF($L20=MATCH(COLUMN()-13,$B20:$E20,0),2,IF($M20=MATCH(COLUMN()-13,$B20:$E20,0),1," "))))
B21: 12 | C21: 14 | D21: 17 | F21: 12 | G21: =INDIRECT(ADDRESS(B21+1,1,,,"Names")) -> 23 | H21: =INDIRECT(ADDRESS(C21+1,1,,,"Names")) -> 37 | I21: =INDIRECT(ADDRESS(D21+1,1,,,"Names")) -> 0 | N21: =IF(ISNA(MATCH(COLUMN()-13,$B21:$E21,0)),"",IF($K21=MATCH(COLUMN()-13,$B21:$E21,0),3,IF($L21=MATCH(COLUMN()-13,$B21:$E21,0),2,IF($M21=MATCH(COLUMN()-13,$B21:$E21,0),1," ")))) | O21: =IF(ISNA(MATCH(COLUMN()-13,$B21:$E21,0)),"",IF($K21=MATCH(COLUMN()-13,$B21:$E21,0),3,IF($L21=MATCH(COLUMN()-13,$B21:$E21,0),2,IF($M21=MATCH(COLUMN()-13,$B21:$E21,0),1," ")))) | P21: =IF(ISNA(MATCH(COLUMN()-13,$B21:$E21,0)),"",IF($K21=MATCH(COLUMN()-13,$B21:$E21,0),3,IF($L21=MATCH(COLUMN()-13,$B21:$E21,0),2,IF($M21=MATCH(COLUMN()-13,$B21:$E21,0),1," ")))) | Q21: =IF(ISNA(MATCH(COLUMN()-13,$B21:$E21,0)),"",IF($K21=MATCH(COLUMN()-13,$B21:$E21,0),3,IF($L21=MATCH(COLUMN()-13,$B21:$E21,0),2,IF($M21=MATCH(COLUMN()-13,$B21:$E21,0),1," ")))) | R21: =IF(ISNA(MATCH(COLUMN()-13,$B21:$E21,0)),"",IF($K21=MATCH(COLUMN()-13,$B21:$E21,0),3,IF($L21=MATCH(COLUMN()-13,$B21:$E21,0),2,IF($M21=MATCH(COLUMN()-13,$B21:$E21,0),1," ")))) | S21: =IF(ISNA(MATCH(COLUMN()-13,$B21:$E21,0)),"",IF($K21=MATCH(COLUMN()-13,$B21:$E21,0),3,IF($L21=MATCH(COLUMN()-13,$B21:$E21,0),2,IF($M21=MATCH(COLUMN()-13,$B21:$E21,0),1," ")))) | T21: =IF(ISNA(MATCH(COLUMN()-13,$B21:$E21,0)),"",IF($K21=MATCH(COLUMN()-13,$B21:$E21,0),3,IF($L21=MATCH(COLUMN()-13,$B21:$E21,0),2,IF($M21=MATCH(COLUMN()-13,$B21:$E21,0),1," ")))) | U21: =IF(ISNA(MATCH(COLUMN()-13,$B21:$E21,0)),"",IF($K21=MATCH(COLUMN()-13,$B21:$E21,0),3,IF($L21=MATCH(COLUMN()-13,$B21:$E21,0),2,IF($M21=MATCH(COLUMN()-13,$B21:$E21,0),1," ")))) | ... AK21: =IF(ISNA(MATCH(COLUMN()-13,$B21:$E21,0)),"",IF($K21=MATCH(COLUMN()-13,$B21:$E21,0),3,IF($L21=MATCH(COLUMN()-13,$B21:$E21,0),2,IF($M21=MATCH(COLUMN()-13,$B21:$E21,0),1," "))))
... B33: 24 | C33: 2 | D33: 5 | F33: 20 | G33: =INDIRECT(ADDRESS(B33+1,1,,,"Names")) -> 0 | H33: =INDIRECT(ADDRESS(C33+1,1,,,"Names")) -> 2 | I33: =INDIRECT(ADDRESS(D33+1,1,,,"Names")) -> 5 | N33: =IF(ISNA(MATCH(COLUMN()-13,$B33:$E33,0)),"",IF($K33=MATCH(COLUMN()-13,$B33:$E33,0),3,IF($L33=MATCH(COLUMN()-13,$B33:$E33,0),2,IF($M33=MATCH(COLUMN()-13,$B33:$E33,0),1," ")))) | O33: =IF(ISNA(MATCH(COLUMN()-13,$B33:$E33,0)),"",IF($K33=MATCH(COLUMN()-13,$B33:$E33,0),3,IF($L33=MATCH(COLUMN()-13,$B33:$E33,0),2,IF($M33=MATCH(COLUMN()-13,$B33:$E33,0),1," ")))) | P33: =IF(ISNA(MATCH(COLUMN()-13,$B33:$E33,0)),"",IF($K33=MATCH(COLUMN()-13,$B33:$E33,0),3,IF($L33=MATCH(COLUMN()-13,$B33:$E33,0),2,IF($M33=MATCH(COLUMN()-13,$B33:$E33,0),1," ")))) | Q33: =IF(ISNA(MATCH(COLUMN()-13,$B33:$E33,0)),"",IF($K33=MATCH(COLUMN()-13,$B33:$E33,0),3,IF($L33=MATCH(COLUMN()-13,$B33:$E33,0),2,IF($M33=MATCH(COLUMN()-13,$B33:$E33,0),1," ")))) | R33: =IF(ISNA(MATCH(COLUMN()-13,$B33:$E33,0)),"",IF($K33=MATCH(COLUMN()-13,$B33:$E33,0),3,IF($L33=MATCH(COLUMN()-13,$B33:$E33,0),2,IF($M33=MATCH(COLUMN()-13,$B33:$E33,0),1," ")))) | S33: =IF(ISNA(MATCH(COLUMN()-13,$B33:$E33,0)),"",IF($K33=MATCH(COLUMN()-13,$B33:$E33,0),3,IF($L33=MATCH(COLUMN()-13,$B33:$E33,0),2,IF($M33=MATCH(COLUMN()-13,$B33:$E33,0),1," ")))) | T33: =IF(ISNA(MATCH(COLUMN()-13,$B33:$E33,0)),"",IF($K33=MATCH(COLUMN()-13,$B33:$E33,0),3,IF($L33=MATCH(COLUMN()-13,$B33:$E33,0),2,IF($M33=MATCH(COLUMN()-13,$B33:$E33,0),1," ")))) | U33: =IF(ISNA(MATCH(COLUMN()-13,$B33:$E33,0)),"",IF($K33=MATCH(COLUMN()-13,$B33:$E33,0),3,IF($L33=MATCH(COLUMN()-13,$B33:$E33,0),2,IF($M33=MATCH(COLUMN()-13,$B33:$E33,0),1," ")))) | ... AK33: =IF(ISNA(MATCH(COLUMN()-13,$B33:$E33,0)),"",IF($K33=MATCH(COLUMN()-13,$B33:$E33,0),3,IF($L33=MATCH(COLUMN()-13,$B33:$E33,0),2,IF($M33=MATCH(COLUMN()-13,$B33:$E33,0),1," "))))
K34: Car's Scores : | N34: =IF(SUM(N10:N29)<1," ",SUM(N10:N29)) | O34: =IF(SUM(O10:O29)<1," ",SUM(O10:O29)) | P34: =IF(SUM(P10:P29)<1," ",SUM(P10:P29)) | Q34: =IF(SUM(Q10:Q29)<1," ",SUM(Q10:Q29)) | R34: =IF(SUM(R10:R29)<1," ",SUM(R10:R29)) | S34: =IF(SUM(S10:S29)<1," ",SUM(S10:S29)) | T34: =IF(SUM(T10:T29)<1," ",SUM(T10:T29)) | U34: =IF(SUM(U10:U29)<1," ",SUM(U10:U29)) | ... AK34: =IF(SUM(AK10:AK29)<1," ",SUM(AK10:AK29))
K35: Finish Place : | N35: =RANK(N34,$N34:$AL34,0) -> #VALUE! | O35: =RANK(O34,$N34:$AL34,0) -> #VALUE! | P35: =RANK(P34,$N34:$AL34,0) -> #VALUE! | Q35: =RANK(Q34,$N34:$AL34,0) -> #VALUE! | R35: =RANK(R34,$N34:$AL34,0) -> #VALUE! | S35: =RANK(S34,$N34:$AL34,0) -> #VALUE! | T35: =RANK(T34,$N34:$AL34,0) -> #VALUE! | U35: =RANK(U34,$N34:$AL34,0) -> #VALUE! | ... AK35: =RANK(AK34,$N34:$AL34,0) -> #VALUE!
N37: =+Names!$B$2 -> Luke | O37: =+Names!$B$3 -> Ro | P37: =+Names!$B$4 -> Caleb | Q37: =+Names!$B$5 -> Zau | R37: =+Names!$B$6 -> Brady | S37: =+Names!$B$7 -> Theo | T37: =+Names!$B$8 -> Jonathan | U37: =+Names!$B$9 -> Brenton | V37: =+Names!$B$10 -> Jospe | W37: =+Names!$B$11 -> Emery | X37: =+Names!$B$12 -> Isaac | Y37: =+Names!$B$13 -> Alain | Z37: =+Names!$B$14 -> Silas | AA37: =+Names!$B$15 -> De | AB37: =+Names!$B$19 -> 0 | AC37: =+Names!$B$20 -> 0 | AD37: =+Names!$B$18 -> 0 | AE37: =+Names!#REF! -> #REF! | AF37: =+Names!#REF! -> #REF! | AG37: =+Names!$B$21 -> 0 | AH37: =+Names!$B$22 -> 0 | AI37: =+Names!$B$23 -> 0 | AJ37: =+Names!$B$24 -> 0 | AK37: =+Names!$B$25 -> 0

Sheet 23 Cars
F1: =+Banner -> Westminster Trailblazers Pinewood Derby
F2: Heat | H2: 1 | I2: =+Names!$C$1 -> Driver | M2: Finish | R2: Legend
F3: Lane 1 | H3: =INDIRECT(ADDRESS(INDIRECT(ADDRESS($H$2+9,2))+1,1,,,"Names")) -> 1 | I3: =INDIRECT(ADDRESS(INDIRECT(ADDRESS($H$2+9,2))+1,2,,,"Names")) -> Luke | M3: =IF(INDIRECT(ADDRESS(9+$H$2,11))=1,"1st",IF(INDIRECT(ADDRESS(9+$H$2,12))=1,"2nd",IF(INDIRECT(ADDRESS(9+$H$2,13))=1,"3rd"," "))) | N3: =IF($K3=4,3,IF($L3=4,2,IF($M3=4,1," "))) | S3: = 1st (3pts)
F4: Lane 2 | H4: =INDIRECT(ADDRESS(INDIRECT(ADDRESS($H$2+9,3))+1,1,,,"Names")) -> 3 | I4: =INDIRECT(ADDRESS(INDIRECT(ADDRESS($H$2+9,3))+1,2,,,"Names")) -> Caleb | M4: =IF(INDIRECT(ADDRESS(9+$H$2,11))=2,"1st",IF(INDIRECT(ADDRESS(9+$H$2,12))=2,"2nd",IF(INDIRECT(ADDRESS(9+$H$2,13))=2,"3rd"," "))) | N4: =IF($K4=4,3,IF($L4=4,2,IF($M4=4,1," "))) | S4: = 2nd (2pts)
F5: Lane 3 | H5: =INDIRECT(ADDRESS(INDIRECT(ADDRESS($H$2+9,4))+1,1,,,"Names")) -> 6 | I5: =INDIRECT(ADDRESS(INDIRECT(ADDRESS($H$2+9,4))+1,2,,,"Names")) -> Theo | M5: =IF(INDIRECT(ADDRESS(9+$H$2,11))=3,"1st",IF(INDIRECT(ADDRESS(9+$H$2,12))=3,"2nd",IF(INDIRECT(ADDRESS(9+$H$2,13))=3,"3rd"," "))) | N5: =IF($K5=4,3,IF($L5=4,2,IF($M5=4,1," "))) | S5: = 3rd (1pt)
G8: Car | K8: Lane Finish | N8: Points
F9: Heat | G9: Lane 1 | H9: Lane 2 | I9: Lane 3 | J9: Lane 4 | K9: 1st | L9: 2nd | M9: 3rd | N9: =+Names!$A$2 -> 1 | O9: =+Names!$A$3 -> 2 | P9: =+Names!$A$4 -> 3 | Q9: =+Names!$A$5 -> 4 | R9: =+Names!$A$6 -> 5 | S9: =+Names!$A$7 -> 6 | T9: =+Names!$A$8 -> 7 | U9: =+Names!$A$9 -> 8 | V9: =+Names!$A$10 -> 9 | W9: =+Names!$A$11 -> 13 | X9: =+Names!$A$12 -> 14 | Y9: =+Names!$A$13 -> 23 | Z9: =+Names!$A$14 -> 30 | AA9: =+Names!$A$15 -> 37 | AB9: =+Names!$A$16 -> 49 | AC9: =+Names!$A$17 -> 99 | AD9: =+Names!$A$18 -> 0 | AE9: =+Names!$A$19 -> 0 | AF9: =+Names!$A$20 -> 0 | AG9: =+Names!$A$21 -> 0 | AH9: =+Names!$A$22 -> 0 | AI9: =+Names!$A$23 -> 0 | AJ9: =+Names!$A$24 -> 0
